Workbook

Sheet MOT Tables INT
A1: Gender | B1: Event | C1: Age | D1: Canada Track | E1: Canada Track Time | F1: Canada Track Time in Seconds | G1: Average Progression Delta | H1: Average Progression Delta VALUE ONLY | I1: Canada Entry Age | J1: Canada Arrival Age | K1: Malaysia Arrival Time (SEA BRONZE) | L1: Malaysia Track Time in Seconds | M1: Malaysia Track Time | N1: Malaysia Track AQUA | P1: Data must be sorted by Gender, Event, Age for the Average Progression Delta forumula to work, values copied in Average Progression Delta VALUE ONLY for refernce if it gets corrupted
A2: F | B2: 100 Back | C2: 13 | D2: 1 | E2: 1:05.85 | F2: =IFERROR(__xludf.DUMMYFUNCTION("IF( REGEXMATCH(E2, "":""), 60*VALUE(INDEX(SPLIT(E2, "":""),1,1)) + VALUE(INDEX(SPLIT(E2, "":""),1,2)), VALUE(E2) )"),65.85) | G2: 0 | H2: 0 | I2: =C2 | J2: =C19 | K2: {=INDEX('Podium Target Times'!$C:$C, MATCH(A2&B2, 'Podium Target Times'!$A:$A&'Podium Target Times'!$B:$B, 0))} | L2: =L3+G3 | M2: =IF(L2<60, TEXT(L2/86400, "ss.00"), IF(L2<600, TEXT(L2/86400, "m:ss.00"), TEXT(L2/86400, "mm:ss.00"))) | N2: =IFERROR(__xludf.DUMMYFUNCTION("LET( gen,$A2, ev,$B2, t,$M2, hdrs, ARRAYFORMULA(UPPER(TRIM(CLEAN(SUBSTITUTE('AQUA POINTS'!$1:$1,CHAR(160),"" ""))))), col, MATCH(UPPER(ev), hdrs, 0), base, INDEX('AQUA POINTS'!$1:$3, IF(gen=""M"",2,3), col), baseSec, IF(ISNUMBER(base), IF(base<"&"1, base*86400, base), IF(REGEXMATCH(base,"":""), VALUE(LEFT(base, FIND("":"",base)-1))*60 + VALUE(MID(base, FIND("":"",base)+1, 99)), VALUE(SUBSTITUTE(base,"","",""."")))), tSec, IF(ISNUMBER(t), IF(t<1, t*86400, t), "&" IF(REGEXMATCH(t,"":""), VALUE(LEFT(t, FIND("":"",t)-1))*60 + VALUE(MID(t, FIND("":"",t)+1, 99)), VALUE(SUBSTITUTE(t,"","",""."")))), INT(1000*(baseSec/tSec)^3) )"),534.0) | P2: =A2 | Q2: =B2 | R2: =C2 | S2: =M2 | T2: =N2
A3: F | B3: 100 Back | C3: 14 | D3: 1 | E3: 1:03.87 | F3: =IFERROR(__xludf.DUMMYFUNCTION("IF( REGEXMATCH(E3, "":""), 60*VALUE(INDEX(SPLIT(E3, "":""),1,1)) + VALUE(INDEX(SPLIT(E3, "":""),1,2)), VALUE(E3) )"),63.87) | G3: =F2-F3 | H3: 1.98 | I3: =C2 | J3: =C19 | K3: {=INDEX('Podium Target Times'!$C:$C, MATCH(A3&B3, 'Podium Target Times'!$A:$A&'Podium Target Times'!$B:$B, 0))} | L3: =L5+G5 | M3: =TEXT(L3/86400, "mm:ss.00") | N3: =IFERROR(__xludf.DUMMYFUNCTION("LET( gen,$A3, ev,$B3, t,$M3, hdrs, ARRAYFORMULA(UPPER(TRIM(CLEAN(SUBSTITUTE('AQUA POINTS'!$1:$1,CHAR(160),"" ""))))), col, MATCH(UPPER(ev), hdrs, 0), base, INDEX('AQUA POINTS'!$1:$3, IF(gen=""M"",2,3), col), baseSec, IF(ISNUMBER(base), IF(base<"&"1, base*86400, base), IF(REGEXMATCH(base,"":""), VALUE(LEFT(base, FIND("":"",base)-1))*60 + VALUE(MID(base, FIND("":"",base)+1, 99)), VALUE(SUBSTITUTE(base,"","",""."")))), tSec, IF(ISNUMBER(t), IF(t<1, t*86400, t), "&" IF(REGEXMATCH(t,"":""), VALUE(LEFT(t, FIND("":"",t)-1))*60 + VALUE(MID(t, FIND("":"",t)+1, 99)), VALUE(SUBSTITUTE(t,"","",""."")))), INT(1000*(baseSec/tSec)^3) )"),581.0) | P3: =A3 | Q3: =B3 | R3: =C3 | S3: =M3 | T3: =N3
A4: F | B4: 100 Back | C4: 14 | D4: 2 | E4: 1:04.75 | F4: =IFERROR(__xludf.DUMMYFUNCTION("IF( REGEXMATCH(E4, "":""), 60*VALUE(INDEX(SPLIT(E4, "":""),1,1)) + VALUE(INDEX(SPLIT(E4, "":""),1,2)), VALUE(E4) )"),64.75) | G4: =F2-F3 | H4: 1.98 | I4: =C2 | J4: =C19 | K4: {=INDEX('Podium Target Times'!$C:$C, MATCH(A4&B4, 'Podium Target Times'!$A:$A&'Podium Target Times'!$B:$B, 0))} | L4: =L5+G5 | M4: =TEXT(L4/86400, "mm:ss.00") | N4: =IFERROR(__xludf.DUMMYFUNCTION("LET( gen,$A4, ev,$B4, t,$M4, hdrs, ARRAYFORMULA(UPPER(TRIM(CLEAN(SUBSTITUTE('AQUA POINTS'!$1:$1,CHAR(160),"" ""))))), col, MATCH(UPPER(ev), hdrs, 0), base, INDEX('AQUA POINTS'!$1:$3, IF(gen=""M"",2,3), col), baseSec, IF(ISNUMBER(base), IF(base<"&"1, base*86400, base), IF(REGEXMATCH(base,"":""), VALUE(LEFT(base, FIND("":"",base)-1))*60 + VALUE(MID(base, FIND("":"",base)+1, 99)), VALUE(SUBSTITUTE(base,"","",""."")))), tSec, IF(ISNUMBER(t), IF(t<1, t*86400, t), "&" IF(REGEXMATCH(t,"":""), VALUE(LEFT(t, FIND("":"",t)-1))*60 + VALUE(MID(t, FIND("":"",t)+1, 99)), VALUE(SUBSTITUTE(t,"","",""."")))), INT(1000*(baseSec/tSec)^3) )"),581.0) | P4: =A5 | Q4: =B5 | R4: =C5 | S4: =M5 | T4: =N5
A5: F | B5: 100 Back | C5: 15 | D5: 1 | E5: 1:02.34 | F5: =IFERROR(__xludf.DUMMYFUNCTION("IF( REGEXMATCH(E5, "":""), 60*VALUE(INDEX(SPLIT(E5, "":""),1,1)) + VALUE(INDEX(SPLIT(E5, "":""),1,2)), VALUE(E5) )"),62.34) | G5: =average(F3-F5,F4-F6) | H5: 1.54 | I5: =C2 | J5: =C19 | K5: {=INDEX('Podium Target Times'!$C:$C, MATCH(A5&B5, 'Podium Target Times'!$A:$A&'Podium Target Times'!$B:$B, 0))} | L5: =L8+G8 | M5: =TEXT(L5/86400, "mm:ss.00") | N5: =IFERROR(__xludf.DUMMYFUNCTION("LET( gen,$A5, ev,$B5, t,$M5, hdrs, ARRAYFORMULA(UPPER(TRIM(CLEAN(SUBSTITUTE('AQUA POINTS'!$1:$1,CHAR(160),"" ""))))), col, MATCH(UPPER(ev), hdrs, 0), base, INDEX('AQUA POINTS'!$1:$3, IF(gen=""M"",2,3), col), baseSec, IF(ISNUMBER(base), IF(base<"&"1, base*86400, base), IF(REGEXMATCH(base,"":""), VALUE(LEFT(base, FIND("":"",base)-1))*60 + VALUE(MID(base, FIND("":"",base)+1, 99)), VALUE(SUBSTITUTE(base,"","",""."")))), tSec, IF(ISNUMBER(t), IF(t<1, t*86400, t), "&" IF(REGEXMATCH(t,"":""), VALUE(LEFT(t, FIND("":"",t)-1))*60 + VALUE(MID(t, FIND("":"",t)+1, 99)), VALUE(SUBSTITUTE(t,"","",""."")))), INT(1000*(baseSec/tSec)^3) )"),623.0) | P5: =A8 | Q5: =B8 | R5: =C8 | S5: =M8 | T5: =N8
A6: F | B6: 100 Back | C6: 15 | D6: 2 | E6: 1:03.20 | F6: =IFERROR(__xludf.DUMMYFUNCTION("IF( REGEXMATCH(E6, "":""), 60*VALUE(INDEX(SPLIT(E6, "":""),1,1)) + VALUE(INDEX(SPLIT(E6, "":""),1,2)), VALUE(E6) )"),63.2) | G6: =average(F3-F5,F4-F6) | H6: 1.54 | I6: =C2 | J6: =C19 | K6: {=INDEX('Podium Target Times'!$C:$C, MATCH(A6&B6, 'Podium Target Times'!$A:$A&'Podium Target Times'!$B:$B, 0))} | L6: =L8+G8 | M6: =TEXT(L6/86400, "mm:ss.00") | N6: =IFERROR(__xludf.DUMMYFUNCTION("LET( gen,$A6, ev,$B6, t,$M6, hdrs, ARRAYFORMULA(UPPER(TRIM(CLEAN(SUBSTITUTE('AQUA POINTS'!$1:$1,CHAR(160),"" ""))))), col, MATCH(UPPER(ev), hdrs, 0), base, INDEX('AQUA POINTS'!$1:$3, IF(gen=""M"",2,3), col), baseSec, IF(ISNUMBER(base), IF(base<"&"1, base*86400, base), IF(REGEXMATCH(base,"":""), VALUE(LEFT(base, FIND("":"",base)-1))*60 + VALUE(MID(base, FIND("":"",base)+1, 99)), VALUE(SUBSTITUTE(base,"","",""."")))), tSec, IF(ISNUMBER(t), IF(t<1, t*86400, t), "&" IF(REGEXMATCH(t,"":""), VALUE(LEFT(t, FIND("":"",t)-1))*60 + VALUE(MID(t, FIND("":"",t)+1, 99)), VALUE(SUBSTITUTE(t,"","",""."")))), INT(1000*(baseSec/tSec)^3) )"),623.0) | P6: =A11 | Q6: =B11 | R6: =C11 | S6: =M11 | T6: =N11
A7: F | B7: 100 Back | C7: 15 | D7: 3 | E7: 1:03.66 | F7: =IFERROR(__xludf.DUMMYFUNCTION("IF( REGEXMATCH(E7, "":""), 60*VALUE(INDEX(SPLIT(E7, "":""),1,1)) + VALUE(INDEX(SPLIT(E7, "":""),1,2)), VALUE(E7) )"),63.66) | G7: =average(F3-F5,F4-F6) | H7: 1.54 | I7: =C2 | J7: =C19 | K7: {=INDEX('Podium Target Times'!$C:$C, MATCH(A7&B7, 'Podium Target Times'!$A:$A&'Podium Target Times'!$B:$B, 0))} | L7: =L8+G8 | M7: =TEXT(L7/86400, "mm:ss.00") | N7: =IFERROR(__xludf.DUMMYFUNCTION("LET( gen,$A7, ev,$B7, t,$M7, hdrs, ARRAYFORMULA(UPPER(TRIM(CLEAN(SUBSTITUTE('AQUA POINTS'!$1:$1,CHAR(160),"" ""))))), col, MATCH(UPPER(ev), hdrs, 0), base, INDEX('AQUA POINTS'!$1:$3, IF(gen=""M"",2,3), col), baseSec, IF(ISNUMBER(base), IF(base<"&"1, base*86400, base), IF(REGEXMATCH(base,"":""), VALUE(LEFT(base, FIND("":"",base)-1))*60 + VALUE(MID(base, FIND("":"",base)+1, 99)), VALUE(SUBSTITUTE(base,"","",""."")))), tSec, IF(ISNUMBER(t), IF(t<1, t*86400, t), "&" IF(REGEXMATCH(t,"":""), VALUE(LEFT(t, FIND("":"",t)-1))*60 + VALUE(MID(t, FIND("":"",t)+1, 99)), VALUE(SUBSTITUTE(t,"","",""."")))), INT(1000*(baseSec/tSec)^3) )"),623.0) | P7: =A14 | Q7: =B14 | R7: =C14 | S7: =M14 | T7: =N14
A8: F | B8: 100 Back | C8: 16 | D8: 1 | E8: 1:01.22 | F8: =IFERROR(__xludf.DUMMYFUNCTION("IF( REGEXMATCH(E8, "":""), 60*VALUE(INDEX(SPLIT(E8, "":""),1,1)) + VALUE(INDEX(SPLIT(E8, "":""),1,2)), VALUE(E8) )"),61.22) | G8: =average(F5-F8,F6-F9,F7-F10) | H8: 1.1333333 | I8: =C2 | J8: =C19 | K8: {=INDEX('Podium Target Times'!$C:$C, MATCH(A8&B8, 'Podium Target Times'!$A:$A&'Podium Target Times'!$B:$B, 0))} | L8: =L11+G11 | M8: =TEXT(L8/86400, "mm:ss.00") | N8: =IFERROR(__xludf.DUMMYFUNCTION("LET( gen,$A8, ev,$B8, t,$M8, hdrs, ARRAYFORMULA(UPPER(TRIM(CLEAN(SUBSTITUTE('AQUA POINTS'!$1:$1,CHAR(160),"" ""))))), col, MATCH(UPPER(ev), hdrs, 0), base, INDEX('AQUA POINTS'!$1:$3, IF(gen=""M"",2,3), col), baseSec, IF(ISNUMBER(base), IF(base<"&"1, base*86400, base), IF(REGEXMATCH(base,"":""), VALUE(LEFT(base, FIND("":"",base)-1))*60 + VALUE(MID(base, FIND("":"",base)+1, 99)), VALUE(SUBSTITUTE(base,"","",""."")))), tSec, IF(ISNUMBER(t), IF(t<1, t*86400, t), "&" IF(REGEXMATCH(t,"":""), VALUE(LEFT(t, FIND("":"",t)-1))*60 + VALUE(MID(t, FIND("":"",t)+1, 99)), VALUE(SUBSTITUTE(t,"","",""."")))), INT(1000*(baseSec/tSec)^3) )"),655.0) | P8: =A16 | Q8: =B16 | R8: =C16 | S8: =M16 | T8: =N16
A9: F | B9: 100 Back | C9: 16 | D9: 2 | E9: 1:02.06 | F9: =IFERROR(__xludf.DUMMYFUNCTION("IF( REGEXMATCH(E9, "":""), 60*VALUE(INDEX(SPLIT(E9, "":""),1,1)) + VALUE(INDEX(SPLIT(E9, "":""),1,2)), VALUE(E9) )"),62.06) | G9: =average(F5-F8,F6-F9,F7-F10) | H9: 1.1333333 | I9: =C2 | J9: =C19 | K9: {=INDEX('Podium Target Times'!$C:$C, MATCH(A9&B9, 'Podium Target Times'!$A:$A&'Podium Target Times'!$B:$B, 0))} | L9: =L11+G11 | M9: =TEXT(L9/86400, "mm:ss.00") | N9: =IFERROR(__xludf.DUMMYFUNCTION("LET( gen,$A9, ev,$B9, t,$M9, hdrs, ARRAYFORMULA(UPPER(TRIM(CLEAN(SUBSTITUTE('AQUA POINTS'!$1:$1,CHAR(160),"" ""))))), col, MATCH(UPPER(ev), hdrs, 0), base, INDEX('AQUA POINTS'!$1:$3, IF(gen=""M"",2,3), col), baseSec, IF(ISNUMBER(base), IF(base<"&"1, base*86400, base), IF(REGEXMATCH(base,"":""), VALUE(LEFT(base, FIND("":"",base)-1))*60 + VALUE(MID(base, FIND("":"",base)+1, 99)), VALUE(SUBSTITUTE(base,"","",""."")))), tSec, IF(ISNUMBER(t), IF(t<1, t*86400, t), "&" IF(REGEXMATCH(t,"":""), VALUE(LEFT(t, FIND("":"",t)-1))*60 + VALUE(MID(t, FIND("":"",t)+1, 99)), VALUE(SUBSTITUTE(t,"","",""."")))), INT(1000*(baseSec/tSec)^3) )"),655.0) | P9: =A18 | Q9: =B18 | R9: =C18 | S9: =M18 | T9: =N18
A10: F | B10: 100 Back | C10: 16 | D10: 3 | E10: 1:02.52 | F10: =IFERROR(__xludf.DUMMYFUNCTION("IF( REGEXMATCH(E10, "":""), 60*VALUE(INDEX(SPLIT(E10, "":""),1,1)) + VALUE(INDEX(SPLIT(E10, "":""),1,2)), VALUE(E10) )"),62.52) | G10: =average(F5-F8,F6-F9,F7-F10) | H10: 1.1333333 | I10: =C2 | J10: =C19 | K10: {=INDEX('Podium Target Times'!$C:$C, MATCH(A10&B10, 'Podium Target Times'!$A:$A&'Podium Target Times'!$B:$B, 0))} | L10: =L11+G11 | M10: =TEXT(L10/86400, "mm:ss.00") | N10: =IFERROR(__xludf.DUMMYFUNCTION("LET( gen,$A10, ev,$B10, t,$M10, hdrs, ARRAYFORMULA(UPPER(TRIM(CLEAN(SUBSTITUTE('AQUA POINTS'!$1:$1,CHAR(160),"" ""))))), col, MATCH(UPPER(ev), hdrs, 0), base, INDEX('AQUA POINTS'!$1:$3, IF(gen=""M"",2,3), col), baseSec, IF(ISNUMBER(base), IF(ba"&"se<1, base*86400, base), IF(REGEXMATCH(base,"":""), VALUE(LEFT(base, FIND("":"",base)-1))*60 + VALUE(MID(base, FIND("":"",base)+1, 99)), VALUE(SUBSTITUTE(base,"","",""."")))), tSec, IF(ISNUMBER(t), IF(t<1, t*86400, t), "&" IF(REGEXMATCH(t,"":""), VALUE(LEFT(t, FIND("":"",t)-1))*60 + VALUE(MID(t, FIND("":"",t)+1, 99)), VALUE(SUBSTITUTE(t,"","",""."")))), INT(1000*(baseSec/tSec)^3) )"),655.0) | P10: =A19 | Q10: =B19 | R10: =C19 | S10: =M19 | T10: =N19
A11: F | B11: 100 Back | C11: 17 | D11: 1 | E11: 1:00.46 | F11: =IFERROR(__xludf.DUMMYFUNCTION("IF( REGEXMATCH(E11, "":""), 60*VALUE(INDEX(SPLIT(E11, "":""),1,1)) + VALUE(INDEX(SPLIT(E11, "":""),1,2)), VALUE(E11) )"),60.46) | G11: =average(F8-F11,F9-F12,F10-F13) | H11: 0.77 | I11: =C2 | J11: =C19 | K11: {=INDEX('Podium Target Times'!$C:$C, MATCH(A11&B11, 'Podium Target Times'!$A:$A&'Podium Target Times'!$B:$B, 0))} | L11: =L14+G14 | M11: =TEXT(L11/86400, "mm:ss.00") | N11: =IFERROR(__xludf.DUMMYFUNCTION("LET( gen,$A11, ev,$B11, t,$M11, hdrs, ARRAYFORMULA(UPPER(TRIM(CLEAN(SUBSTITUTE('AQUA POINTS'!$1:$1,CHAR(160),"" ""))))), col, MATCH(UPPER(ev), hdrs, 0), base, INDEX('AQUA POINTS'!$1:$3, IF(gen=""M"",2,3), col), baseSec, IF(ISNUMBER(base), IF(ba"&"se<1, base*86400, base), IF(REGEXMATCH(base,"":""), VALUE(LEFT(base, FIND("":"",base)-1))*60 + VALUE(MID(base, FIND("":"",base)+1, 99)), VALUE(SUBSTITUTE(base,"","",""."")))), tSec, IF(ISNUMBER(t), IF(t<1, t*86400, t), "&" IF(REGEXMATCH(t,"":""), VALUE(LEFT(t, FIND("":"",t)-1))*60 + VALUE(MID(t, FIND("":"",t)+1, 99)), VALUE(SUBSTITUTE(t,"","",""."")))), INT(1000*(baseSec/tSec)^3) )"),679.0)
A12: F | B12: 100 Back | C12: 17 | D12: 2 | E12: 1:01.29 | F12: =IFERROR(__xludf.DUMMYFUNCTION("IF( REGEXMATCH(E12, "":""), 60*VALUE(INDEX(SPLIT(E12, "":""),1,1)) + VALUE(INDEX(SPLIT(E12, "":""),1,2)), VALUE(E12) )"),61.29) | G12: =average(F8-F11,F9-F12,F10-F13) | H12: 0.77 | I12: =C2 | J12: =C19 | K12: {=INDEX('Podium Target Times'!$C:$C, MATCH(A12&B12, 'Podium Target Times'!$A:$A&'Podium Target Times'!$B:$B, 0))} | L12: =L14+G14 | M12: =TEXT(L12/86400, "mm:ss.00") | N12: =IFERROR(__xludf.DUMMYFUNCTION("LET( gen,$A12, ev,$B12, t,$M12, hdrs, ARRAYFORMULA(UPPER(TRIM(CLEAN(SUBSTITUTE('AQUA POINTS'!$1:$1,CHAR(160),"" ""))))), col, MATCH(UPPER(ev), hdrs, 0), base, INDEX('AQUA POINTS'!$1:$3, IF(gen=""M"",2,3), col), baseSec, IF(ISNUMBER(base), IF(ba"&"se<1, base*86400, base), IF(REGEXMATCH(base,"":""), VALUE(LEFT(base, FIND("":"",base)-1))*60 + VALUE(MID(base, FIND("":"",base)+1, 99)), VALUE(SUBSTITUTE(base,"","",""."")))), tSec, IF(ISNUMBER(t), IF(t<1, t*86400, t), "&" IF(REGEXMATCH(t,"":""), VALUE(LEFT(t, FIND("":"",t)-1))*60 + VALUE(MID(t, FIND("":"",t)+1, 99)), VALUE(SUBSTITUTE(t,"","",""."")))), INT(1000*(baseSec/tSec)^3) )"),679.0)
A13: F | B13: 100 Back | C13: 17 | D13: 3 | E13: 1:01.74 | F13: =IFERROR(__xludf.DUMMYFUNCTION("IF( REGEXMATCH(E13, "":""), 60*VALUE(INDEX(SPLIT(E13, "":""),1,1)) + VALUE(INDEX(SPLIT(E13, "":""),1,2)), VALUE(E13) )"),61.74) | G13: =average(F8-F11,F9-F12,F10-F13) | H13: 0.77 | I13: =C2 | J13: =C19 | K13: {=INDEX('Podium Target Times'!$C:$C, MATCH(A13&B13, 'Podium Target Times'!$A:$A&'Podium Target Times'!$B:$B, 0))} | L13: =L14+G14 | M13: =TEXT(L13/86400, "mm:ss.00") | N13: =IFERROR(__xludf.DUMMYFUNCTION("LET( gen,$A13, ev,$B13, t,$M13, hdrs, ARRAYFORMULA(UPPER(TRIM(CLEAN(SUBSTITUTE('AQUA POINTS'!$1:$1,CHAR(160),"" ""))))), col, MATCH(UPPER(ev), hdrs, 0), base, INDEX('AQUA POINTS'!$1:$3, IF(gen=""M"",2,3), col), baseSec, IF(ISNUMBER(base), IF(ba"&"se<1, base*86400, base), IF(REGEXMATCH(base,"":""), VALUE(LEFT(base, FIND("":"",base)-1))*60 + VALUE(MID(base, FIND("":"",base)+1, 99)), VALUE(SUBSTITUTE(base,"","",""."")))), tSec, IF(ISNUMBER(t), IF(t<1, t*86400, t), "&" IF(REGEXMATCH(t,"":""), VALUE(LEFT(t, FIND("":"",t)-1))*60 + VALUE(MID(t, FIND("":"",t)+1, 99)), VALUE(SUBSTITUTE(t,"","",""."")))), INT(1000*(baseSec/tSec)^3) )"),679.0)
A14: F | B14: 100 Back | C14: 18 | D14: 2 | E14: 1:00.79 | F14: =IFERROR(__xludf.DUMMYFUNCTION("IF( REGEXMATCH(E14, "":""), 60*VALUE(INDEX(SPLIT(E14, "":""),1,1)) + VALUE(INDEX(SPLIT(E14, "":""),1,2)), VALUE(E14) )"),60.79) | G14: =average(F12-F14,F13-F15) | H14: 0.505 | I14: =C2 | J14: =C19 | K14: {=INDEX('Podium Target Times'!$C:$C, MATCH(A14&B14, 'Podium Target Times'!$A:$A&'Podium Target Times'!$B:$B, 0))} | L14: =L16+G16 | M14: =TEXT(L14/86400, "mm:ss.00") | N14: =IFERROR(__xludf.DUMMYFUNCTION("LET( gen,$A14, ev,$B14, t,$M14, hdrs, ARRAYFORMULA(UPPER(TRIM(CLEAN(SUBSTITUTE('AQUA POINTS'!$1:$1,CHAR(160),"" ""))))), col, MATCH(UPPER(ev), hdrs, 0), base, INDEX('AQUA POINTS'!$1:$3, IF(gen=""M"",2,3), col), baseSec, IF(ISNUMBER(base), IF(ba"&"se<1, base*86400, base), IF(REGEXMATCH(base,"":""), VALUE(LEFT(base, FIND("":"",base)-1))*60 + VALUE(MID(base, FIND("":"",base)+1, 99)), VALUE(SUBSTITUTE(base,"","",""."")))), tSec, IF(ISNUMBER(t), IF(t<1, t*86400, t), "&" IF(REGEXMATCH(t,"":""), VALUE(LEFT(t, FIND("":"",t)-1))*60 + VALUE(MID(t, FIND("":"",t)+1, 99)), VALUE(SUBSTITUTE(t,"","",""."")))), INT(1000*(baseSec/tSec)^3) )"),695.0)
A15: F | B15: 100 Back | C15: 18 | D15: 3 | E15: 1:01.23 | F15: =IFERROR(__xludf.DUMMYFUNCTION("IF( REGEXMATCH(E15, "":""), 60*VALUE(INDEX(SPLIT(E15, "":""),1,1)) + VALUE(INDEX(SPLIT(E15, "":""),1,2)), VALUE(E15) )"),61.23) | G15: =average(F12-F14,F13-F15) | H15: 0.505 | I15: =C2 | J15: =C19 | K15: {=INDEX('Podium Target Times'!$C:$C, MATCH(A15&B15, 'Podium Target Times'!$A:$A&'Podium Target Times'!$B:$B, 0))} | L15: =L16+G16 | M15: =TEXT(L15/86400, "mm:ss.00") | N15: =IFERROR(__xludf.DUMMYFUNCTION("LET( gen,$A15, ev,$B15, t,$M15, hdrs, ARRAYFORMULA(UPPER(TRIM(CLEAN(SUBSTITUTE('AQUA POINTS'!$1:$1,CHAR(160),"" ""))))), col, MATCH(UPPER(ev), hdrs, 0), base, INDEX('AQUA POINTS'!$1:$3, IF(gen=""M"",2,3), col), baseSec, IF(ISNUMBER(base), IF(ba"&"se<1, base*86400, base), IF(REGEXMATCH(base,"":""), VALUE(LEFT(base, FIND("":"",base)-1))*60 + VALUE(MID(base, FIND("":"",base)+1, 99)), VALUE(SUBSTITUTE(base,"","",""."")))), tSec, IF(ISNUMBER(t), IF(t<1, t*86400, t), "&" IF(REGEXMATCH(t,"":""), VALUE(LEFT(t, FIND("":"",t)-1))*60 + VALUE(MID(t, FIND("":"",t)+1, 99)), VALUE(SUBSTITUTE(t,"","",""."")))), INT(1000*(baseSec/tSec)^3) )"),695.0)
A16: F | B16: 100 Back | C16: 19 | D16: 2 | E16: 1:00.46 | F16: =IFERROR(__xludf.DUMMYFUNCTION("IF( REGEXMATCH(E16, "":""), 60*VALUE(INDEX(SPLIT(E16, "":""),1,1)) + VALUE(INDEX(SPLIT(E16, "":""),1,2)), VALUE(E16) )"),60.46) | G16: =average(F14-F16,F15-F17) | H16: 0.33 | I16: =C2 | J16: =C19 | K16: {=INDEX('Podium Target Times'!$C:$C, MATCH(A16&B16, 'Podium Target Times'!$A:$A&'Podium Target Times'!$B:$B, 0))} | L16: =L18+G18 | M16: =TEXT(L16/86400, "mm:ss.00") | N16: =IFERROR(__xludf.DUMMYFUNCTION("LET( gen,$A16, ev,$B16, t,$M16, hdrs, ARRAYFORMULA(UPPER(TRIM(CLEAN(SUBSTITUTE('AQUA POINTS'!$1:$1,CHAR(160),"" ""))))), col, MATCH(UPPER(ev), hdrs, 0), base, INDEX('AQUA POINTS'!$1:$3, IF(gen=""M"",2,3), col), baseSec, IF(ISNUMBER(base), IF(ba"&"se<1, base*86400, base), IF(REGEXMATCH(base,"":""), VALUE(LEFT(base, FIND("":"",base)-1))*60 + VALUE(MID(base, FIND("":"",base)+1, 99)), VALUE(SUBSTITUTE(base,"","",""."")))), tSec, IF(ISNUMBER(t), IF(t<1, t*86400, t), "&" IF(REGEXMATCH(t,"":""), VALUE(LEFT(t, FIND("":"",t)-1))*60 + VALUE(MID(t, FIND("":"",t)+1, 99)), VALUE(SUBSTITUTE(t,"","",""."")))), INT(1000*(baseSec/tSec)^3) )"),706.0)
A17: F | B17: 100 Back | C17: 19 | D17: 3 | E17: 1:00.90 | F17: =IFERROR(__xludf.DUMMYFUNCTION("IF( REGEXMATCH(E17, "":""), 60*VALUE(INDEX(SPLIT(E17, "":""),1,1)) + VALUE(INDEX(SPLIT(E17, "":""),1,2)), VALUE(E17) )"),60.9) | G17: =average(F14-F16,F15-F17) | H17: 0.33 | I17: =C2 | J17: =C19 | K17: {=INDEX('Podium Target Times'!$C:$C, MATCH(A17&B17, 'Podium Target Times'!$A:$A&'Podium Target Times'!$B:$B, 0))} | L17: =L18+G18 | M17: =TEXT(L17/86400, "mm:ss.00") | N17: =IFERROR(__xludf.DUMMYFUNCTION("LET( gen,$A17, ev,$B17, t,$M17, hdrs, ARRAYFORMULA(UPPER(TRIM(CLEAN(SUBSTITUTE('AQUA POINTS'!$1:$1,CHAR(160),"" ""))))), col, MATCH(UPPER(ev), hdrs, 0), base, INDEX('AQUA POINTS'!$1:$3, IF(gen=""M"",2,3), col), baseSec, IF(ISNUMBER(base), IF(ba"&"se<1, base*86400, base), IF(REGEXMATCH(base,"":""), VALUE(LEFT(base, FIND("":"",base)-1))*60 + VALUE(MID(base, FIND("":"",base)+1, 99)), VALUE(SUBSTITUTE(base,"","",""."")))), tSec, IF(ISNUMBER(t), IF(t<1, t*86400, t), "&" IF(REGEXMATCH(t,"":""), VALUE(LEFT(t, FIND("":"",t)-1))*60 + VALUE(MID(t, FIND("":"",t)+1, 99)), VALUE(SUBSTITUTE(t,"","",""."")))), INT(1000*(baseSec/tSec)^3) )"),706.0)
A18: F | B18: 100 Back | C18: 20 | D18: 3 | E18: 1:00.66 | F18: =IFERROR(__xludf.DUMMYFUNCTION("IF( REGEXMATCH(E18, "":""), 60*VALUE(INDEX(SPLIT(E18, "":""),1,1)) + VALUE(INDEX(SPLIT(E18, "":""),1,2)), VALUE(E18) )"),60.66) | G18: =F17-F18 | H18: 0.24 | I18: =C2 | J18: =C19 | K18: {=INDEX('Podium Target Times'!$C:$C, MATCH(A18&B18, 'Podium Target Times'!$A:$A&'Podium Target Times'!$B:$B, 0))} | L18: =L19+G19 | M18: =TEXT(L18/86400, "mm:ss.00") | N18: =IFERROR(__xludf.DUMMYFUNCTION("LET( gen,$A18, ev,$B18, t,$M18, hdrs, ARRAYFORMULA(UPPER(TRIM(CLEAN(SUBSTITUTE('AQUA POINTS'!$1:$1,CHAR(160),"" ""))))), col, MATCH(UPPER(ev), hdrs, 0), base, INDEX('AQUA POINTS'!$1:$3, IF(gen=""M"",2,3), col), baseSec, IF(ISNUMBER(base), IF(ba"&"se<1, base*86400, base), IF(REGEXMATCH(base,"":""), VALUE(LEFT(base, FIND("":"",base)-1))*60 + VALUE(MID(base, FIND("":"",base)+1, 99)), VALUE(SUBSTITUTE(base,"","",""."")))), tSec, IF(ISNUMBER(t), IF(t<1, t*86400, t), "&" IF(REGEXMATCH(t,"":""), VALUE(LEFT(t, FIND("":"",t)-1))*60 + VALUE(MID(t, FIND("":"",t)+1, 99)), VALUE(SUBSTITUTE(t,"","",""."")))), INT(1000*(baseSec/tSec)^3) )"),714.0)
A19: F | B19: 100 Back | C19: 21 | D19: 3 | E19: 1:00.46 | F19: =IFERROR(__xludf.DUMMYFUNCTION("IF( REGEXMATCH(E19, "":""), 60*VALUE(INDEX(SPLIT(E19, "":""),1,1)) + VALUE(INDEX(SPLIT(E19, "":""),1,2)), VALUE(E19) )"),60.46) | G19: =F18-F19 | H19: 0.2 | I19: =C2 | J19: =C19 | K19: {=INDEX('Podium Target Times'!$C:$C, MATCH(A19&B19, 'Podium Target Times'!$A:$A&'Podium Target Times'!$B:$B, 0))} | L19: =K19 | M19: =TEXT(L19/86400, "mm:ss.00") | N19: =IFERROR(__xludf.DUMMYFUNCTION("LET( gen,$A19, ev,$B19, t,$M19, hdrs, ARRAYFORMULA(UPPER(TRIM(CLEAN(SUBSTITUTE('AQUA POINTS'!$1:$1,CHAR(160),"" ""))))), col, MATCH(UPPER(ev), hdrs, 0), base, INDEX('AQUA POINTS'!$1:$3, IF(gen=""M"",2,3), col), baseSec, IF(ISNUMBER(base), IF(ba"&"se<1, base*86400, base), IF(REGEXMATCH(base,"":""), VALUE(LEFT(base, FIND("":"",base)-1))*60 + VALUE(MID(base, FIND("":"",base)+1, 99)), VALUE(SUBSTITUTE(base,"","",""."")))), tSec, IF(ISNUMBER(t), IF(t<1, t*86400, t), "&" IF(REGEXMATCH(t,"":""), VALUE(LEFT(t, FIND("":"",t)-1))*60 + VALUE(MID(t, FIND("":"",t)+1, 99)), VALUE(SUBSTITUTE(t,"","",""."")))), INT(1000*(baseSec/tSec)^3) )"),721.0)
A20: F | B20: 100 Breast | C20: 15 | D20: 1 | E20: 1:09.68 | F20: =IFERROR(__xludf.DUMMYFUNCTION("IF( REGEXMATCH(E20, "":""), 60*VALUE(INDEX(SPLIT(E20, "":""),1,1)) + VALUE(INDEX(SPLIT(E20, "":""),1,2)), VALUE(E20) )"),69.68) | G20: 0 | H20: 0 | I20: =C20 | J20: =C37 | K20: {=INDEX('Podium Target Times'!$C:$C, MATCH(A20&B20, 'Podium Target Times'!$A:$A&'Podium Target Times'!$B:$B, 0))} | L20: =L21+G21 | M20: =TEXT(L20/86400, "mm:ss.00") | N20: =IFERROR(__xludf.DUMMYFUNCTION("LET( gen,$A20, ev,$B20, t,$M20, hdrs, ARRAYFORMULA(UPPER(TRIM(CLEAN(SUBSTITUTE('AQUA POINTS'!$1:$1,CHAR(160),"" ""))))), col, MATCH(UPPER(ev), hdrs, 0), base, INDEX('AQUA POINTS'!$1:$3, IF(gen=""M"",2,3), col), baseSec, IF(ISNUMBER(base), IF(ba"&"se<1, base*86400, base), IF(REGEXMATCH(base,"":""), VALUE(LEFT(base, FIND("":"",base)-1))*60 + VALUE(MID(base, FIND("":"",base)+1, 99)), VALUE(SUBSTITUTE(base,"","",""."")))), tSec, IF(ISNUMBER(t), IF(t<1, t*86400, t), "&" IF(REGEXMATCH(t,"":""), VALUE(LEFT(t, FIND("":"",t)-1))*60 + VALUE(MID(t, FIND("":"",t)+1, 99)), VALUE(SUBSTITUTE(t,"","",""."")))), INT(1000*(baseSec/tSec)^3) )"),625.0) | P20: =A20 | Q20: =B20 | R20: =C20 | S20: =M20 | T20: =N20
A21: F | B21: 100 Breast | C21: 16 | D21: 1 | E21: 1:08.45 | F21: =IFERROR(__xludf.DUMMYFUNCTION("IF( REGEXMATCH(E21, "":""), 60*VALUE(INDEX(SPLIT(E21, "":""),1,1)) + VALUE(INDEX(SPLIT(E21, "":""),1,2)), VALUE(E21) )"),68.45) | G21: =F20-F21 | H21: 1.23 | I21: =C20 | J21: =C37 | K21: {=INDEX('Podium Target Times'!$C:$C, MATCH(A21&B21, 'Podium Target Times'!$A:$A&'Podium Target Times'!$B:$B, 0))} | L21: =L23+G23 | M21: =TEXT(L21/86400, "mm:ss.00") | N21: =IFERROR(__xludf.DUMMYFUNCTION("LET( gen,$A21, ev,$B21, t,$M21, hdrs, ARRAYFORMULA(UPPER(TRIM(CLEAN(SUBSTITUTE('AQUA POINTS'!$1:$1,CHAR(160),"" ""))))), col, MATCH(UPPER(ev), hdrs, 0), base, INDEX('AQUA POINTS'!$1:$3, IF(gen=""M"",2,3), col), baseSec, IF(ISNUMBER(base), IF(ba"&"se<1, base*86400, base), IF(REGEXMATCH(base,"":""), VALUE(LEFT(base, FIND("":"",base)-1))*60 + VALUE(MID(base, FIND("":"",base)+1, 99)), VALUE(SUBSTITUTE(base,"","",""."")))), tSec, IF(ISNUMBER(t), IF(t<1, t*86400, t), "&" IF(REGEXMATCH(t,"":""), VALUE(LEFT(t, FIND("":"",t)-1))*60 + VALUE(MID(t, FIND("":"",t)+1, 99)), VALUE(SUBSTITUTE(t,"","",""."")))), INT(1000*(baseSec/tSec)^3) )"),657.0) | P21: =A21 | Q21: =B21 | R21: =C21 | S21: =M21 | T21: =N21
A22: F | B22: 100 Breast | C22: 16 | D22: 2 | E22: 1:09.15 | F22: =IFERROR(__xludf.DUMMYFUNCTION("IF( REGEXMATCH(E22, "":""), 60*VALUE(INDEX(SPLIT(E22, "":""),1,1)) + VALUE(INDEX(SPLIT(E22, "":""),1,2)), VALUE(E22) )"),69.15) | G22: =F20-F21 | H22: 1.23 | I22: =C20 | J22: =C37 | K22: {=INDEX('Podium Target Times'!$C:$C, MATCH(A22&B22, 'Podium Target Times'!$A:$A&'Podium Target Times'!$B:$B, 0))} | L22: =L23+G23 | M22: =TEXT(L22/86400, "mm:ss.00") | N22: =IFERROR(__xludf.DUMMYFUNCTION("LET( gen,$A22, ev,$B22, t,$M22, hdrs, ARRAYFORMULA(UPPER(TRIM(CLEAN(SUBSTITUTE('AQUA POINTS'!$1:$1,CHAR(160),"" ""))))), col, MATCH(UPPER(ev), hdrs, 0), base, INDEX('AQUA POINTS'!$1:$3, IF(gen=""M"",2,3), col), baseSec, IF(ISNUMBER(base), IF(ba"&"se<1, base*86400, base), IF(REGEXMATCH(base,"":""), VALUE(LEFT(base, FIND("":"",base)-1))*60 + VALUE(MID(base, FIND("":"",base)+1, 99)), VALUE(SUBSTITUTE(base,"","",""."")))), tSec, IF(ISNUMBER(t), IF(t<1, t*86400, t), "&" IF(REGEXMATCH(t,"":""), VALUE(LEFT(t, FIND("":"",t)-1))*60 + VALUE(MID(t, FIND("":"",t)+1, 99)), VALUE(SUBSTITUTE(t,"","",""."")))), INT(1000*(baseSec/tSec)^3) )"),657.0) | P22: =A23 | Q22: =B23 | R22: =C23 | S22: =M23 | T22: =N23
A23: F | B23: 100 Breast | C23: 17 | D23: 1 | E23: 1:07.71 | F23: =IFERROR(__xludf.DUMMYFUNCTION("IF( REGEXMATCH(E23, "":""), 60*VALUE(INDEX(SPLIT(E23, "":""),1,1)) + VALUE(INDEX(SPLIT(E23, "":""),1,2)), VALUE(E23) )"),67.71) | G23: =average(F21-F23,F22-F24) | H23: 0.745 | I23: =C20 | J23: =C37 | K23: {=INDEX('Podium Target Times'!$C:$C, MATCH(A23&B23, 'Podium Target Times'!$A:$A&'Podium Target Times'!$B:$B, 0))} | L23: =L26+G26 | M23: =TEXT(L23/86400, "mm:ss.00") | N23: =IFERROR(__xludf.DUMMYFUNCTION("LET( gen,$A23, ev,$B23, t,$M23, hdrs, ARRAYFORMULA(UPPER(TRIM(CLEAN(SUBSTITUTE('AQUA POINTS'!$1:$1,CHAR(160),"" ""))))), col, MATCH(UPPER(ev), hdrs, 0), base, INDEX('AQUA POINTS'!$1:$3, IF(gen=""M"",2,3), col), baseSec, IF(ISNUMBER(base), IF(ba"&"se<1, base*86400, base), IF(REGEXMATCH(base,"":""), VALUE(LEFT(base, FIND("":"",base)-1))*60 + VALUE(MID(base, FIND("":"",base)+1, 99)), VALUE(SUBSTITUTE(base,"","",""."")))), tSec, IF(ISNUMBER(t), IF(t<1, t*86400, t), "&" IF(REGEXMATCH(t,"":""), VALUE(LEFT(t, FIND("":"",t)-1))*60 + VALUE(MID(t, FIND("":"",t)+1, 99)), VALUE(SUBSTITUTE(t,"","",""."")))), INT(1000*(baseSec/tSec)^3) )"),677.0) | P23: =A26 | Q23: =B26 | R23: =C26 | S23: =M26 | T23: =N26
A24: F | B24: 100 Breast | C24: 17 | D24: 2 | E24: 1:08.40 | F24: =IFERROR(__xludf.DUMMYFUNCTION("IF( REGEXMATCH(E24, "":""), 60*VALUE(INDEX(SPLIT(E24, "":""),1,1)) + VALUE(INDEX(SPLIT(E24, "":""),1,2)), VALUE(E24) )"),68.4) | G24: =average(F21-F23,F22-F24) | H24: 0.745 | I24: =C20 | J24: =C37 | K24: {=INDEX('Podium Target Times'!$C:$C, MATCH(A24&B24, 'Podium Target Times'!$A:$A&'Podium Target Times'!$B:$B, 0))} | L24: =L26+G26 | M24: =TEXT(L24/86400, "mm:ss.00") | N24: =IFERROR(__xludf.DUMMYFUNCTION("LET( gen,$A24, ev,$B24, t,$M24, hdrs, ARRAYFORMULA(UPPER(TRIM(CLEAN(SUBSTITUTE('AQUA POINTS'!$1:$1,CHAR(160),"" ""))))), col, MATCH(UPPER(ev), hdrs, 0), base, INDEX('AQUA POINTS'!$1:$3, IF(gen=""M"",2,3), col), baseSec, IF(ISNUMBER(base), IF(ba"&"se<1, base*86400, base), IF(REGEXMATCH(base,"":""), VALUE(LEFT(base, FIND("":"",base)-1))*60 + VALUE(MID(base, FIND("":"",base)+1, 99)), VALUE(SUBSTITUTE(base,"","",""."")))), tSec, IF(ISNUMBER(t), IF(t<1, t*86400, t), "&" IF(REGEXMATCH(t,"":""), VALUE(LEFT(t, FIND("":"",t)-1))*60 + VALUE(MID(t, FIND("":"",t)+1, 99)), VALUE(SUBSTITUTE(t,"","",""."")))), INT(1000*(baseSec/tSec)^3) )"),677.0) | P24: =A29 | Q24: =B29 | R24: =C29 | S24: =M29 | T24: =N29
A25: F | B25: 100 Breast | C25: 17 | D25: 3 | E25: 1:08.94 | F25: =IFERROR(__xludf.DUMMYFUNCTION("IF( REGEXMATCH(E25, "":""), 60*VALUE(INDEX(SPLIT(E25, "":""),1,1)) + VALUE(INDEX(SPLIT(E25, "":""),1,2)), VALUE(E25) )"),68.94) | G25: =average(F21-F23,F22-F24) | H25: 0.745 | I25: =C20 | J25: =C37 | K25: {=INDEX('Podium Target Times'!$C:$C, MATCH(A25&B25, 'Podium Target Times'!$A:$A&'Podium Target Times'!$B:$B, 0))} | L25: =L26+G26 | M25: =TEXT(L25/86400, "mm:ss.00") | N25: =IFERROR(__xludf.DUMMYFUNCTION("LET( gen,$A25, ev,$B25, t,$M25, hdrs, ARRAYFORMULA(UPPER(TRIM(CLEAN(SUBSTITUTE('AQUA POINTS'!$1:$1,CHAR(160),"" ""))))), col, MATCH(UPPER(ev), hdrs, 0), base, INDEX('AQUA POINTS'!$1:$3, IF(gen=""M"",2,3), col), baseSec, IF(ISNUMBER(base), IF(ba"&"se<1, base*86400, base), IF(REGEXMATCH(base,"":""), VALUE(LEFT(base, FIND("":"",base)-1))*60 + VALUE(MID(base, FIND("":"",base)+1, 99)), VALUE(SUBSTITUTE(base,"","",""."")))), tSec, IF(ISNUMBER(t), IF(t<1, t*86400, t), "&" IF(REGEXMATCH(t,"":""), VALUE(LEFT(t, FIND("":"",t)-1))*60 + VALUE(MID(t, FIND("":"",t)+1, 99)), VALUE(SUBSTITUTE(t,"","",""."")))), INT(1000*(baseSec/tSec)^3) )"),677.0) | P25: =A32 | Q25: =B32 | R25: =C32 | S25: =M32 | T25: =N32
A26: F | B26: 100 Breast | C26: 18 | D26: 1 | E26: 1:07.24 | F26: =IFERROR(__xludf.DUMMYFUNCTION("IF( REGEXMATCH(E26, "":""), 60*VALUE(INDEX(SPLIT(E26, "":""),1,1)) + VALUE(INDEX(SPLIT(E26, "":""),1,2)), VALUE(E26) )"),67.24) | G26: =average(F23-F26,F24-F27,F25-F28) | H26: 0.47666667 | I26: =C20 | J26: =C37 | K26: {=INDEX('Podium Target Times'!$C:$C, MATCH(A26&B26, 'Podium Target Times'!$A:$A&'Podium Target Times'!$B:$B, 0))} | L26: =L29+G29 | M26: =TEXT(L26/86400, "mm:ss.00") | N26: =IFERROR(__xludf.DUMMYFUNCTION("LET( gen,$A26, ev,$B26, t,$M26, hdrs, ARRAYFORMULA(UPPER(TRIM(CLEAN(SUBSTITUTE('AQUA POINTS'!$1:$1,CHAR(160),"" ""))))), col, MATCH(UPPER(ev), hdrs, 0), base, INDEX('AQUA POINTS'!$1:$3, IF(gen=""M"",2,3), col), baseSec, IF(ISNUMBER(base), IF(ba"&"se<1, base*86400, base), IF(REGEXMATCH(base,"":""), VALUE(LEFT(base, FIND("":"",base)-1))*60 + VALUE(MID(base, FIND("":"",base)+1, 99)), VALUE(SUBSTITUTE(base,"","",""."")))), tSec, IF(ISNUMBER(t), IF(t<1, t*86400, t), "&" IF(REGEXMATCH(t,"":""), VALUE(LEFT(t, FIND("":"",t)-1))*60 + VALUE(MID(t, FIND("":"",t)+1, 99)), VALUE(SUBSTITUTE(t,"","",""."")))), INT(1000*(baseSec/tSec)^3) )"),691.0) | P26: =A34 | Q26: =B34 | R26: =C34 | S26: =M34 | T26: =N34
A27: F | B27: 100 Breast | C27: 18 | D27: 2 | E27: 1:07.92 | F27: =IFERROR(__xludf.DUMMYFUNCTION("IF( REGEXMATCH(E27, "":""), 60*VALUE(INDEX(SPLIT(E27, "":""),1,1)) + VALUE(INDEX(SPLIT(E27, "":""),1,2)), VALUE(E27) )"),67.92) | G27: =average(F23-F26,F24-F27,F25-F28) | H27: 0.47666667 | I27: =C20 | J27: =C37 | K27: {=INDEX('Podium Target Times'!$C:$C, MATCH(A27&B27, 'Podium Target Times'!$A:$A&'Podium Target Times'!$B:$B, 0))} | L27: =L29+G29 | M27: =TEXT(L27/86400, "mm:ss.00") | N27: =IFERROR(__xludf.DUMMYFUNCTION("LET( gen,$A27, ev,$B27, t,$M27, hdrs, ARRAYFORMULA(UPPER(TRIM(CLEAN(SUBSTITUTE('AQUA POINTS'!$1:$1,CHAR(160),"" ""))))), col, MATCH(UPPER(ev), hdrs, 0), base, INDEX('AQUA POINTS'!$1:$3, IF(gen=""M"",2,3), col), baseSec, IF(ISNUMBER(base), IF(ba"&"se<1, base*86400, base), IF(REGEXMATCH(base,"":""), VALUE(LEFT(base, FIND("":"",base)-1))*60 + VALUE(MID(base, FIND("":"",base)+1, 99)), VALUE(SUBSTITUTE(base,"","",""."")))), tSec, IF(ISNUMBER(t), IF(t<1, t*86400, t), "&" IF(REGEXMATCH(t,"":""), VALUE(LEFT(t, FIND("":"",t)-1))*60 + VALUE(MID(t, FIND("":"",t)+1, 99)), VALUE(SUBSTITUTE(t,"","",""."")))), INT(1000*(baseSec/tSec)^3) )"),691.0) | P27: =A36 | Q27: =B36 | R27: =C36 | S27: =M36 | T27: =N36
A28: F | B28: 100 Breast | C28: 18 | D28: 3 | E28: 1:08.46 | F28: =IFERROR(__xludf.DUMMYFUNCTION("IF( REGEXMATCH(E28, "":""), 60*VALUE(INDEX(SPLIT(E28, "":""),1,1)) + VALUE(INDEX(SPLIT(E28, "":""),1,2)), VALUE(E28) )"),68.46000000000001) | G28: =average(F23-F26,F24-F27,F25-F28) | H28: 0.47666667 | I28: =C20 | J28: =C37 | K28: {=INDEX('Podium Target Times'!$C:$C, MATCH(A28&B28, 'Podium Target Times'!$A:$A&'Podium Target Times'!$B:$B, 0))} | L28: =L29+G29 | M28: =TEXT(L28/86400, "mm:ss.00") | N28: =IFERROR(__xludf.DUMMYFUNCTION("LET( gen,$A28, ev,$B28, t,$M28, hdrs, ARRAYFORMULA(UPPER(TRIM(CLEAN(SUBSTITUTE('AQUA POINTS'!$1:$1,CHAR(160),"" ""))))), col, MATCH(UPPER(ev), hdrs, 0), base, INDEX('AQUA POINTS'!$1:$3, IF(gen=""M"",2,3), col), baseSec, IF(ISNUMBER(base), IF(ba"&"se<1, base*86400, base), IF(REGEXMATCH(base,"":""), VALUE(LEFT(base, FIND("":"",base)-1))*60 + VALUE(MID(base, FIND("":"",base)+1, 99)), VALUE(SUBSTITUTE(base,"","",""."")))), tSec, IF(ISNUMBER(t), IF(t<1, t*86400, t), "&" IF(REGEXMATCH(t,"":""), VALUE(LEFT(t, FIND("":"",t)-1))*60 + VALUE(MID(t, FIND("":"",t)+1, 99)), VALUE(SUBSTITUTE(t,"","",""."")))), INT(1000*(baseSec/tSec)^3) )"),691.0) | P28: =A37 | Q28: =B37 | R28: =C37 | S28: =M37 | T28: =N37
A29: F | B29: 100 Breast | C29: 19 | D29: 1 | E29: 1:06.87 | F29: =IFERROR(__xludf.DUMMYFUNCTION("IF( REGEXMATCH(E29, "":""), 60*VALUE(INDEX(SPLIT(E29, "":""),1,1)) + VALUE(INDEX(SPLIT(E29, "":""),1,2)), VALUE(E29) )"),66.87) | G29: =average(F26-F29,F27-F30,F28-F31) | H29: 0.37333333 | I29: =C20 | J29: =C37 | K29: {=INDEX('Podium Target Times'!$C:$C, MATCH(A29&B29, 'Podium Target Times'!$A:$A&'Podium Target Times'!$B:$B, 0))} | L29: =L32+G32 | M29: =TEXT(L29/86400, "mm:ss.00") | N29: =IFERROR(__xludf.DUMMYFUNCTION("LET( gen,$A29, ev,$B29, t,$M29, hdrs, ARRAYFORMULA(UPPER(TRIM(CLEAN(SUBSTITUTE('AQUA POINTS'!$1:$1,CHAR(160),"" ""))))), col, MATCH(UPPER(ev), hdrs, 0), base, INDEX('AQUA POINTS'!$1:$3, IF(gen=""M"",2,3), col), baseSec, IF(ISNUMBER(base), IF(ba"&"se<1, base*86400, base), IF(REGEXMATCH(base,"":""), VALUE(LEFT(base, FIND("":"",base)-1))*60 + VALUE(MID(base, FIND("":"",base)+1, 99)), VALUE(SUBSTITUTE(base,"","",""."")))), tSec, IF(ISNUMBER(t), IF(t<1, t*86400, t), "&" IF(REGEXMATCH(t,"":""), VALUE(LEFT(t, FIND("":"",t)-1))*60 + VALUE(MID(t, FIND("":"",t)+1, 99)), VALUE(SUBSTITUTE(t,"","",""."")))), INT(1000*(baseSec/tSec)^3) )"),702.0)
A30: F | B30: 100 Breast | C30: 19 | D30: 2 | E30: 1:07.55 | F30: =IFERROR(__xludf.DUMMYFUNCTION("IF( REGEXMATCH(E30, "":""), 60*VALUE(INDEX(SPLIT(E30, "":""),1,1)) + VALUE(INDEX(SPLIT(E30, "":""),1,2)), VALUE(E30) )"),67.55) | G30: =average(F26-F29,F27-F30,F28-F31) | H30: 0.37333333 | I30: =C20 | J30: =C37 | K30: {=INDEX('Podium Target Times'!$C:$C, MATCH(A30&B30, 'Podium Target Times'!$A:$A&'Podium Target Times'!$B:$B, 0))} | L30: =L32+G32 | M30: =TEXT(L30/86400, "mm:ss.00") | N30: =IFERROR(__xludf.DUMMYFUNCTION("LET( gen,$A30, ev,$B30, t,$M30, hdrs, ARRAYFORMULA(UPPER(TRIM(CLEAN(SUBSTITUTE('AQUA POINTS'!$1:$1,CHAR(160),"" ""))))), col, MATCH(UPPER(ev), hdrs, 0), base, INDEX('AQUA POINTS'!$1:$3, IF(gen=""M"",2,3), col), baseSec, IF(ISNUMBER(base), IF(ba"&"se<1, base*86400, base), IF(REGEXMATCH(base,"":""), VALUE(LEFT(base, FIND("":"",base)-1))*60 + VALUE(MID(base, FIND("":"",base)+1, 99)), VALUE(SUBSTITUTE(base,"","",""."")))), tSec, IF(ISNUMBER(t), IF(t<1, t*86400, t), "&" IF(REGEXMATCH(t,"":""), VALUE(LEFT(t, FIND("":"",t)-1))*60 + VALUE(MID(t, FIND("":"",t)+1, 99)), VALUE(SUBSTITUTE(t,"","",""."")))), INT(1000*(baseSec/tSec)^3) )"),702.0)
A31: F | B31: 100 Breast | C31: 19 | D31: 3 | E31: 1:08.08 | F31: =IFERROR(__xludf.DUMMYFUNCTION("IF( REGEXMATCH(E31, "":""), 60*VALUE(INDEX(SPLIT(E31, "":""),1,1)) + VALUE(INDEX(SPLIT(E31, "":""),1,2)), VALUE(E31) )"),68.08) | G31: =average(F26-F29,F27-F30,F28-F31) | H31: 0.37333333 | I31: =C20 | J31: =C37 | K31: {=INDEX('Podium Target Times'!$C:$C, MATCH(A31&B31, 'Podium Target Times'!$A:$A&'Podium Target Times'!$B:$B, 0))} | L31: =L32+G32 | M31: =TEXT(L31/86400, "mm:ss.00") | N31: =IFERROR(__xludf.DUMMYFUNCTION("LET( gen,$A31, ev,$B31, t,$M31, hdrs, ARRAYFORMULA(UPPER(TRIM(CLEAN(SUBSTITUTE('AQUA POINTS'!$1:$1,CHAR(160),"" ""))))), col, MATCH(UPPER(ev), hdrs, 0), base, INDEX('AQUA POINTS'!$1:$3, IF(gen=""M"",2,3), col), baseSec, IF(ISNUMBER(base), IF(ba"&"se<1, base*86400, base), IF(REGEXMATCH(base,"":""), VALUE(LEFT(base, FIND("":"",base)-1))*60 + VALUE(MID(base, FIND("":"",base)+1, 99)), VALUE(SUBSTITUTE(base,"","",""."")))), tSec, IF(ISNUMBER(t), IF(t<1, t*86400, t), "&" IF(REGEXMATCH(t,"":""), VALUE(LEFT(t, FIND("":"",t)-1))*60 + VALUE(MID(t, FIND("":"",t)+1, 99)), VALUE(SUBSTITUTE(t,"","",""."")))), INT(1000*(baseSec/tSec)^3) )"),702.0)
A32: F | B32: 100 Breast | C32: 20 | D32: 2 | E32: 1:07.20 | F32: =IFERROR(__xludf.DUMMYFUNCTION("IF( REGEXMATCH(E32, "":""), 60*VALUE(INDEX(SPLIT(E32, "":""),1,1)) + VALUE(INDEX(SPLIT(E32, "":""),1,2)), VALUE(E32) )"),67.2) | G32: =average(F30-F32,F31-F33) | H32: 0.35 | I32: =C20 | J32: =C37 | K32: {=INDEX('Podium Target Times'!$C:$C, MATCH(A32&B32, 'Podium Target Times'!$A:$A&'Podium Target Times'!$B:$B, 0))} | L32: =L34+G34 | M32: =TEXT(L32/86400, "mm:ss.00") | N32: =IFERROR(__xludf.DUMMYFUNCTION("LET( gen,$A32, ev,$B32, t,$M32, hdrs, ARRAYFORMULA(UPPER(TRIM(CLEAN(SUBSTITUTE('AQUA POINTS'!$1:$1,CHAR(160),"" ""))))), col, MATCH(UPPER(ev), hdrs, 0), base, INDEX('AQUA POINTS'!$1:$3, IF(gen=""M"",2,3), col), baseSec, IF(ISNUMBER(base), IF(ba"&"se<1, base*86400, base), IF(REGEXMATCH(base,"":""), VALUE(LEFT(base, FIND("":"",base)-1))*60 + VALUE(MID(base, FIND("":"",base)+1, 99)), VALUE(SUBSTITUTE(base,"","",""."")))), tSec, IF(ISNUMBER(t), IF(t<1, t*86400, t), "&" IF(REGEXMATCH(t,"":""), VALUE(LEFT(t, FIND("":"",t)-1))*60 + VALUE(MID(t, FIND("":"",t)+1, 99)), VALUE(SUBSTITUTE(t,"","",""."")))), INT(1000*(baseSec/tSec)^3) )"),712.0)
A33: F | B33: 100 Breast | C33: 20 | D33: 3 | E33: 1:07.73 | F33: =IFERROR(__xludf.DUMMYFUNCTION("IF( REGEXMATCH(E33, "":""), 60*VALUE(INDEX(SPLIT(E33, "":""),1,1)) + VALUE(INDEX(SPLIT(E33, "":""),1,2)), VALUE(E33) )"),67.73) | G33: =average(F30-F32,F31-F33) | H33: 0.35 | I33: =C20 | J33: =C37 | K33: {=INDEX('Podium Target Times'!$C:$C, MATCH(A33&B33, 'Podium Target Times'!$A:$A&'Podium Target Times'!$B:$B, 0))} | L33: =L34+G34 | M33: =TEXT(L33/86400, "mm:ss.00") | N33: =IFERROR(__xludf.DUMMYFUNCTION("LET( gen,$A33, ev,$B33, t,$M33, hdrs, ARRAYFORMULA(UPPER(TRIM(CLEAN(SUBSTITUTE('AQUA POINTS'!$1:$1,CHAR(160),"" ""))))), col, MATCH(UPPER(ev), hdrs, 0), base, INDEX('AQUA POINTS'!$1:$3, IF(gen=""M"",2,3), col), baseSec, IF(ISNUMBER(base), IF(ba"&"se<1, base*86400, base), IF(REGEXMATCH(base,"":""), VALUE(LEFT(base, FIND("":"",base)-1))*60 + VALUE(MID(base, FIND("":"",base)+1, 99)), VALUE(SUBSTITUTE(base,"","",""."")))), tSec, IF(ISNUMBER(t), IF(t<1, t*86400, t), "&" IF(REGEXMATCH(t,"":""), VALUE(LEFT(t, FIND("":"",t)-1))*60 + VALUE(MID(t, FIND("":"",t)+1, 99)), VALUE(SUBSTITUTE(t,"","",""."")))), INT(1000*(baseSec/tSec)^3) )"),712.0)
A34: F | B34: 100 Breast | C34: 21 | D34: 2 | E34: 1:06.87 | F34: =IFERROR(__xludf.DUMMYFUNCTION("IF( REGEXMATCH(E34, "":""), 60*VALUE(INDEX(SPLIT(E34, "":""),1,1)) + VALUE(INDEX(SPLIT(E34, "":""),1,2)), VALUE(E34) )"),66.87) | G34: =average(F32-F34,F33-F35) | H34: 0.335 | I34: =C20 | J34: =C37 | K34: {=INDEX('Podium Target Times'!$C:$C, MATCH(A34&B34, 'Podium Target Times'!$A:$A&'Podium Target Times'!$B:$B, 0))} | L34: =L36+G36 | M34: =TEXT(L34/86400, "mm:ss.00") | N34: =IFERROR(__xludf.DUMMYFUNCTION("LET( gen,$A34, ev,$B34, t,$M34, hdrs, ARRAYFORMULA(UPPER(TRIM(CLEAN(SUBSTITUTE('AQUA POINTS'!$1:$1,CHAR(160),"" ""))))), col, MATCH(UPPER(ev), hdrs, 0), base, INDEX('AQUA POINTS'!$1:$3, IF(gen=""M"",2,3), col), baseSec, IF(ISNUMBER(base), IF(ba"&"se<1, base*86400, base), IF(REGEXMATCH(base,"":""), VALUE(LEFT(base, FIND("":"",base)-1))*60 + VALUE(MID(base, FIND("":"",base)+1, 99)), VALUE(SUBSTITUTE(base,"","",""."")))), tSec, IF(ISNUMBER(t), IF(t<1, t*86400, t), "&" IF(REGEXMATCH(t,"":""), VALUE(LEFT(t, FIND("":"",t)-1))*60 + VALUE(MID(t, FIND("":"",t)+1, 99)), VALUE(SUBSTITUTE(t,"","",""."")))), INT(1000*(baseSec/tSec)^3) )"),722.0)
A35: F | B35: 100 Breast | C35: 21 | D35: 3 | E35: 1:07.39 | F35: =IFERROR(__xludf.DUMMYFUNCTION("IF( REGEXMATCH(E35, "":""), 60*VALUE(INDEX(SPLIT(E35, "":""),1,1)) + VALUE(INDEX(SPLIT(E35, "":""),1,2)), VALUE(E35) )"),67.39) | G35: =average(F32-F34,F33-F35) | H35: 0.335 | I35: =C20 | J35: =C37 | K35: {=INDEX('Podium Target Times'!$C:$C, MATCH(A35&B35, 'Podium Target Times'!$A:$A&'Podium Target Times'!$B:$B, 0))} | L35: =L36+G36 | M35: =TEXT(L35/86400, "mm:ss.00") | N35: =IFERROR(__xludf.DUMMYFUNCTION("LET( gen,$A35, ev,$B35, t,$M35, hdrs, ARRAYFORMULA(UPPER(TRIM(CLEAN(SUBSTITUTE('AQUA POINTS'!$1:$1,CHAR(160),"" ""))))), col, MATCH(UPPER(ev), hdrs, 0), base, INDEX('AQUA POINTS'!$1:$3, IF(gen=""M"",2,3), col), baseSec, IF(ISNUMBER(base), IF(ba"&"se<1, base*86400, base), IF(REGEXMATCH(base,"":""), VALUE(LEFT(base, FIND("":"",base)-1))*60 + VALUE(MID(base, FIND("":"",base)+1, 99)), VALUE(SUBSTITUTE(base,"","",""."")))), tSec, IF(ISNUMBER(t), IF(t<1, t*86400, t), "&" IF(REGEXMATCH(t,"":""), VALUE(LEFT(t, FIND("":"",t)-1))*60 + VALUE(MID(t, FIND("":"",t)+1, 99)), VALUE(SUBSTITUTE(t,"","",""."")))), INT(1000*(baseSec/tSec)^3) )"),722.0)
A36: F | B36: 100 Breast | C36: 22 | D36: 3 | E36: 1:07.10 | F36: =IFERROR(__xludf.DUMMYFUNCTION("IF( REGEXMATCH(E36, "":""), 60*VALUE(INDEX(SPLIT(E36, "":""),1,1)) + VALUE(INDEX(SPLIT(E36, "":""),1,2)), VALUE(E36) )"),67.1) | G36: =F35-F36 | H36: 0.29 | I36: =C20 | J36: =C37 | K36: {=INDEX('Podium Target Times'!$C:$C, MATCH(A36&B36, 'Podium Target Times'!$A:$A&'Podium Target Times'!$B:$B, 0))} | L36: =L37+G37 | M36: =TEXT(L36/86400, "mm:ss.00") | N36: =IFERROR(__xludf.DUMMYFUNCTION("LET( gen,$A36, ev,$B36, t,$M36, hdrs, ARRAYFORMULA(UPPER(TRIM(CLEAN(SUBSTITUTE('AQUA POINTS'!$1:$1,CHAR(160),"" ""))))), col, MATCH(UPPER(ev), hdrs, 0), base, INDEX('AQUA POINTS'!$1:$3, IF(gen=""M"",2,3), col), baseSec, IF(ISNUMBER(base), IF(ba"&"se<1, base*86400, base), IF(REGEXMATCH(base,"":""), VALUE(LEFT(base, FIND("":"",base)-1))*60 + VALUE(MID(base, FIND("":"",base)+1, 99)), VALUE(SUBSTITUTE(base,"","",""."")))), tSec, IF(ISNUMBER(t), IF(t<1, t*86400, t), "&" IF(REGEXMATCH(t,"":""), VALUE(LEFT(t, FIND("":"",t)-1))*60 + VALUE(MID(t, FIND("":"",t)+1, 99)), VALUE(SUBSTITUTE(t,"","",""."")))), INT(1000*(baseSec/tSec)^3) )"),731.0)
A37: F | B37: 100 Breast | C37: 23 | D37: 3 | E37: 1:06.87 | F37: =IFERROR(__xludf.DUMMYFUNCTION("IF( REGEXMATCH(E37, "":""), 60*VALUE(INDEX(SPLIT(E37, "":""),1,1)) + VALUE(INDEX(SPLIT(E37, "":""),1,2)), VALUE(E37) )"),66.87) | G37: =F36-F37 | H37: 0.23 | I37: =C20 | J37: =C37 | K37: {=INDEX('Podium Target Times'!$C:$C, MATCH(A37&B37, 'Podium Target Times'!$A:$A&'Podium Target Times'!$B:$B, 0))} | L37: =K37 | M37: =TEXT(L37/86400, "mm:ss.00") | N37: =IFERROR(__xludf.DUMMYFUNCTION("LET( gen,$A37, ev,$B37, t,$M37, hdrs, ARRAYFORMULA(UPPER(TRIM(CLEAN(SUBSTITUTE('AQUA POINTS'!$1:$1,CHAR(160),"" ""))))), col, MATCH(UPPER(ev), hdrs, 0), base, INDEX('AQUA POINTS'!$1:$3, IF(gen=""M"",2,3), col), baseSec, IF(ISNUMBER(base), IF(ba"&"se<1, base*86400, base), IF(REGEXMATCH(base,"":""), VALUE(LEFT(base, FIND("":"",base)-1))*60 + VALUE(MID(base, FIND("":"",base)+1, 99)), VALUE(SUBSTITUTE(base,"","",""."")))), tSec, IF(ISNUMBER(t), IF(t<1, t*86400, t), "&" IF(REGEXMATCH(t,"":""), VALUE(LEFT(t, FIND("":"",t)-1))*60 + VALUE(MID(t, FIND("":"",t)+1, 99)), VALUE(SUBSTITUTE(t,"","",""."")))), INT(1000*(baseSec/tSec)^3) )"),738.0)
A38: F | B38: 100 Fly | C38: 15 | D38: 1 | E38: 1:01.67 | F38: =IFERROR(__xludf.DUMMYFUNCTION("IF( REGEXMATCH(E38, "":""), 60*VALUE(INDEX(SPLIT(E38, "":""),1,1)) + VALUE(INDEX(SPLIT(E38, "":""),1,2)), VALUE(E38) )"),61.67) | G38: 0 | H38: 0 | I38: =C38 | J38: =C55 | K38: {=INDEX('Podium Target Times'!$C:$C, MATCH(A38&B38, 'Podium Target Times'!$A:$A&'Podium Target Times'!$B:$B, 0))} | L38: =L39+G39 | M38: =TEXT(L38/86400, "mm:ss.00") | N38: =IFERROR(__xludf.DUMMYFUNCTION("LET( gen,$A38, ev,$B38, t,$M38, hdrs, ARRAYFORMULA(UPPER(TRIM(CLEAN(SUBSTITUTE('AQUA POINTS'!$1:$1,CHAR(160),"" ""))))), col, MATCH(UPPER(ev), hdrs, 0), base, INDEX('AQUA POINTS'!$1:$3, IF(gen=""M"",2,3), col), baseSec, IF(ISNUMBER(base), IF(ba"&"se<1, base*86400, base), IF(REGEXMATCH(base,"":""), VALUE(LEFT(base, FIND("":"",base)-1))*60 + VALUE(MID(base, FIND("":"",base)+1, 99)), VALUE(SUBSTITUTE(base,"","",""."")))), tSec, IF(ISNUMBER(t), IF(t<1, t*86400, t), "&" IF(REGEXMATCH(t,"":""), VALUE(LEFT(t, FIND("":"",t)-1))*60 + VALUE(MID(t, FIND("":"",t)+1, 99)), VALUE(SUBSTITUTE(t,"","",""."")))), INT(1000*(baseSec/tSec)^3) )"),620.0) | P38: =A38 | Q38: =B38 | R38: =C38 | S38: =M38 | T38: =N38
A39: F | B39: 100 Fly | C39: 16 | D39: 1 | E39: 1:00.43 | F39: =IFERROR(__xludf.DUMMYFUNCTION("IF( REGEXMATCH(E39, "":""), 60*VALUE(INDEX(SPLIT(E39, "":""),1,1)) + VALUE(INDEX(SPLIT(E39, "":""),1,2)), VALUE(E39) )"),60.43) | G39: =F38-F39 | H39: 1.24 | I39: =C38 | J39: =C55 | K39: {=INDEX('Podium Target Times'!$C:$C, MATCH(A39&B39, 'Podium Target Times'!$A:$A&'Podium Target Times'!$B:$B, 0))} | L39: =L41+G41 | M39: =TEXT(L39/86400, "mm:ss.00") | N39: =IFERROR(__xludf.DUMMYFUNCTION("LET( gen,$A39, ev,$B39, t,$M39, hdrs, ARRAYFORMULA(UPPER(TRIM(CLEAN(SUBSTITUTE('AQUA POINTS'!$1:$1,CHAR(160),"" ""))))), col, MATCH(UPPER(ev), hdrs, 0), base, INDEX('AQUA POINTS'!$1:$3, IF(gen=""M"",2,3), col), baseSec, IF(ISNUMBER(base), IF(ba"&"se<1, base*86400, base), IF(REGEXMATCH(base,"":""), VALUE(LEFT(base, FIND("":"",base)-1))*60 + VALUE(MID(base, FIND("":"",base)+1, 99)), VALUE(SUBSTITUTE(base,"","",""."")))), tSec, IF(ISNUMBER(t), IF(t<1, t*86400, t), "&" IF(REGEXMATCH(t,"":""), VALUE(LEFT(t, FIND("":"",t)-1))*60 + VALUE(MID(t, FIND("":"",t)+1, 99)), VALUE(SUBSTITUTE(t,"","",""."")))), INT(1000*(baseSec/tSec)^3) )"),657.0) | P39: =A39 | Q39: =B39 | R39: =C39 | S39: =M39 | T39: =N39
A40: F | B40: 100 Fly | C40: 16 | D40: 2 | E40: 1:01.15 | F40: =IFERROR(__xludf.DUMMYFUNCTION("IF( REGEXMATCH(E40, "":""), 60*VALUE(INDEX(SPLIT(E40, "":""),1,1)) + VALUE(INDEX(SPLIT(E40, "":""),1,2)), VALUE(E40) )"),61.15) | G40: =F38-F39 | H40: 1.24 | I40: =C38 | J40: =C55 | K40: {=INDEX('Podium Target Times'!$C:$C, MATCH(A40&B40, 'Podium Target Times'!$A:$A&'Podium Target Times'!$B:$B, 0))} | L40: =L41+G41 | M40: =TEXT(L40/86400, "mm:ss.00") | N40: =IFERROR(__xludf.DUMMYFUNCTION("LET( gen,$A40, ev,$B40, t,$M40, hdrs, ARRAYFORMULA(UPPER(TRIM(CLEAN(SUBSTITUTE('AQUA POINTS'!$1:$1,CHAR(160),"" ""))))), col, MATCH(UPPER(ev), hdrs, 0), base, INDEX('AQUA POINTS'!$1:$3, IF(gen=""M"",2,3), col), baseSec, IF(ISNUMBER(base), IF(ba"&"se<1, base*86400, base), IF(REGEXMATCH(base,"":""), VALUE(LEFT(base, FIND("":"",base)-1))*60 + VALUE(MID(base, FIND("":"",base)+1, 99)), VALUE(SUBSTITUTE(base,"","",""."")))), tSec, IF(ISNUMBER(t), IF(t<1, t*86400, t), "&" IF(REGEXMATCH(t,"":""), VALUE(LEFT(t, FIND("":"",t)-1))*60 + VALUE(MID(t, FIND("":"",t)+1, 99)), VALUE(SUBSTITUTE(t,"","",""."")))), INT(1000*(baseSec/tSec)^3) )"),657.0) | P40: =A41 | Q40: =B41 | R40: =C41 | S40: =M41 | T40: =N41
...

Sheet MOT Tables 25
A1: Gender | B1: Event | C1: Age | D1: Canada Track | E1: Canada Track Time | F1: Canada Track Time in Seconds | G1: Average Progression Delta | H1: Average Progression Delta VALUE ONLY | I1: Canada Entry Age | J1: Canada Arrival Age | K1: Malaysia Arrival Time (SEA BRONZE) | L1: Malaysia Track Time in Seconds | M1: Malaysia Track Time | N1: Malaysia Track AQUA | P1: Data must be sorted by Gender, Event, Age for the Average Progression Delta forumula to work, values copied in Average Progression Delta VALUE ONLY for refernce if it gets corrupted
A2: F | B2: 100 Back | C2: 13 | D2: 1 | E2: 1:05.85 | F2: =IFERROR(__xludf.DUMMYFUNCTION("IF( REGEXMATCH(E2, "":""), 60*VALUE(INDEX(SPLIT(E2, "":""),1,1)) + VALUE(INDEX(SPLIT(E2, "":""),1,2)), VALUE(E2) )"),65.85) | G2: 0 | H2: 0 | I2: =C2 | J2: =C19 | K2: {=INDEX('Podium Target Times'!$C:$C, MATCH(A2&B2, 'Podium Target Times'!$A:$A&'Podium Target Times'!$B:$B, 0))} | L2: =L3+G3 | M2: =IF(L2<60, TEXT(L2,"0.00"), IF(L2<600, TEXT(L2/86400,"m:ss.00"), TEXT(L2/86400,"mm:ss.00"))) | N2: =IFERROR(__xludf.DUMMYFUNCTION("LET( gen,$A2, ev,$B2, t,$M2, hdrs, ARRAYFORMULA(UPPER(TRIM(CLEAN(SUBSTITUTE('AQUA POINTS'!$1:$1,CHAR(160),"" ""))))), col, MATCH(UPPER(ev), hdrs, 0), base, INDEX('AQUA POINTS'!$1:$3, IF(gen=""M"",2,3), col), baseSec, IF(ISNUMBER(base), IF(base<"&"1, base*86400, base), IF(REGEXMATCH(base,"":""), VALUE(LEFT(base, FIND("":"",base)-1))*60 + VALUE(MID(base, FIND("":"",base)+1, 99)), VALUE(SUBSTITUTE(base,"","",""."")))), tSec, IF(ISNUMBER(t), IF(t<1, t*86400, t), "&" IF(REGEXMATCH(t,"":""), VALUE(LEFT(t, FIND("":"",t)-1))*60 + VALUE(MID(t, FIND("":"",t)+1, 99)), VALUE(SUBSTITUTE(t,"","",""."")))), INT(1000*(baseSec/tSec)^3) )"),516.0) | P2: =A2 | Q2: =B2 | R2: =C2 | S2: =M2 | T2: =N2
A3: F | B3: 100 Back | C3: 14 | D3: 1 | E3: 1:03.87 | F3: =IFERROR(__xludf.DUMMYFUNCTION("IF( REGEXMATCH(E3, "":""), 60*VALUE(INDEX(SPLIT(E3, "":""),1,1)) + VALUE(INDEX(SPLIT(E3, "":""),1,2)), VALUE(E3) )"),63.87) | G3: =F2-F3 | H3: 1.98 | I3: =C2 | J3: =C19 | K3: {=INDEX('Podium Target Times'!$C:$C, MATCH(A3&B3, 'Podium Target Times'!$A:$A&'Podium Target Times'!$B:$B, 0))} | L3: =L5+G5 | M3: =IF(L3<60, TEXT(L3,"0.00"), IF(L3<600, TEXT(L3/86400,"m:ss.00"), TEXT(L3/86400,"mm:ss.00"))) | N3: =IFERROR(__xludf.DUMMYFUNCTION("LET( gen,$A3, ev,$B3, t,$M3, hdrs, ARRAYFORMULA(UPPER(TRIM(CLEAN(SUBSTITUTE('AQUA POINTS'!$1:$1,CHAR(160),"" ""))))), col, MATCH(UPPER(ev), hdrs, 0), base, INDEX('AQUA POINTS'!$1:$3, IF(gen=""M"",2,3), col), baseSec, IF(ISNUMBER(base), IF(base<"&"1, base*86400, base), IF(REGEXMATCH(base,"":""), VALUE(LEFT(base, FIND("":"",base)-1))*60 + VALUE(MID(base, FIND("":"",base)+1, 99)), VALUE(SUBSTITUTE(base,"","",""."")))), tSec, IF(ISNUMBER(t), IF(t<1, t*86400, t), "&" IF(REGEXMATCH(t,"":""), VALUE(LEFT(t, FIND("":"",t)-1))*60 + VALUE(MID(t, FIND("":"",t)+1, 99)), VALUE(SUBSTITUTE(t,"","",""."")))), INT(1000*(baseSec/tSec)^3) )"),561.0) | P3: =A3 | Q3: =B3 | R3: =C3 | S3: =M3 | T3: =N3
A4: F | B4: 100 Back | C4: 14 | D4: 2 | E4: 1:04.75 | F4: =IFERROR(__xludf.DUMMYFUNCTION("IF( REGEXMATCH(E4, "":""), 60*VALUE(INDEX(SPLIT(E4, "":""),1,1)) + VALUE(INDEX(SPLIT(E4, "":""),1,2)), VALUE(E4) )"),64.75) | G4: =F2-F3 | H4: 1.98 | I4: =C2 | J4: =C19 | K4: {=INDEX('Podium Target Times'!$C:$C, MATCH(A4&B4, 'Podium Target Times'!$A:$A&'Podium Target Times'!$B:$B, 0))} | L4: =L5+G5 | M4: =IF(L4<60, TEXT(L4,"0.00"), IF(L4<600, TEXT(L4/86400,"m:ss.00"), TEXT(L4/86400,"mm:ss.00"))) | N4: =IFERROR(__xludf.DUMMYFUNCTION("LET( gen,$A4, ev,$B4, t,$M4, hdrs, ARRAYFORMULA(UPPER(TRIM(CLEAN(SUBSTITUTE('AQUA POINTS'!$1:$1,CHAR(160),"" ""))))), col, MATCH(UPPER(ev), hdrs, 0), base, INDEX('AQUA POINTS'!$1:$3, IF(gen=""M"",2,3), col), baseSec, IF(ISNUMBER(base), IF(base<"&"1, base*86400, base), IF(REGEXMATCH(base,"":""), VALUE(LEFT(base, FIND("":"",base)-1))*60 + VALUE(MID(base, FIND("":"",base)+1, 99)), VALUE(SUBSTITUTE(base,"","",""."")))), tSec, IF(ISNUMBER(t), IF(t<1, t*86400, t), "&" IF(REGEXMATCH(t,"":""), VALUE(LEFT(t, FIND("":"",t)-1))*60 + VALUE(MID(t, FIND("":"",t)+1, 99)), VALUE(SUBSTITUTE(t,"","",""."")))), INT(1000*(baseSec/tSec)^3) )"),561.0) | P4: =A5 | Q4: =B5 | R4: =C5 | S4: =M5 | T4: =N5
A5: F | B5: 100 Back | C5: 15 | D5: 1 | E5: 1:02.34 | F5: =IFERROR(__xludf.DUMMYFUNCTION("IF( REGEXMATCH(E5, "":""), 60*VALUE(INDEX(SPLIT(E5, "":""),1,1)) + VALUE(INDEX(SPLIT(E5, "":""),1,2)), VALUE(E5) )"),62.34) | G5: =average(F3-F5,F4-F6) | H5: 1.54 | I5: =C2 | J5: =C19 | K5: {=INDEX('Podium Target Times'!$C:$C, MATCH(A5&B5, 'Podium Target Times'!$A:$A&'Podium Target Times'!$B:$B, 0))} | L5: =L8+G8 | M5: =IF(L5<60, TEXT(L5,"0.00"), IF(L5<600, TEXT(L5/86400,"m:ss.00"), TEXT(L5/86400,"mm:ss.00"))) | N5: =IFERROR(__xludf.DUMMYFUNCTION("LET( gen,$A5, ev,$B5, t,$M5, hdrs, ARRAYFORMULA(UPPER(TRIM(CLEAN(SUBSTITUTE('AQUA POINTS'!$1:$1,CHAR(160),"" ""))))), col, MATCH(UPPER(ev), hdrs, 0), base, INDEX('AQUA POINTS'!$1:$3, IF(gen=""M"",2,3), col), baseSec, IF(ISNUMBER(base), IF(base<"&"1, base*86400, base), IF(REGEXMATCH(base,"":""), VALUE(LEFT(base, FIND("":"",base)-1))*60 + VALUE(MID(base, FIND("":"",base)+1, 99)), VALUE(SUBSTITUTE(base,"","",""."")))), tSec, IF(ISNUMBER(t), IF(t<1, t*86400, t), "&" IF(REGEXMATCH(t,"":""), VALUE(LEFT(t, FIND("":"",t)-1))*60 + VALUE(MID(t, FIND("":"",t)+1, 99)), VALUE(SUBSTITUTE(t,"","",""."")))), INT(1000*(baseSec/tSec)^3) )"),601.0) | P5: =A8 | Q5: =B8 | R5: =C8 | S5: =M8 | T5: =N8
A6: F | B6: 100 Back | C6: 15 | D6: 2 | E6: 1:03.20 | F6: =IFERROR(__xludf.DUMMYFUNCTION("IF( REGEXMATCH(E6, "":""), 60*VALUE(INDEX(SPLIT(E6, "":""),1,1)) + VALUE(INDEX(SPLIT(E6, "":""),1,2)), VALUE(E6) )"),63.2) | G6: =average(F3-F5,F4-F6) | H6: 1.54 | I6: =C2 | J6: =C19 | K6: {=INDEX('Podium Target Times'!$C:$C, MATCH(A6&B6, 'Podium Target Times'!$A:$A&'Podium Target Times'!$B:$B, 0))} | L6: =L8+G8 | M6: =IF(L6<60, TEXT(L6,"0.00"), IF(L6<600, TEXT(L6/86400,"m:ss.00"), TEXT(L6/86400,"mm:ss.00"))) | N6: =IFERROR(__xludf.DUMMYFUNCTION("LET( gen,$A6, ev,$B6, t,$M6, hdrs, ARRAYFORMULA(UPPER(TRIM(CLEAN(SUBSTITUTE('AQUA POINTS'!$1:$1,CHAR(160),"" ""))))), col, MATCH(UPPER(ev), hdrs, 0), base, INDEX('AQUA POINTS'!$1:$3, IF(gen=""M"",2,3), col), baseSec, IF(ISNUMBER(base), IF(base<"&"1, base*86400, base), IF(REGEXMATCH(base,"":""), VALUE(LEFT(base, FIND("":"",base)-1))*60 + VALUE(MID(base, FIND("":"",base)+1, 99)), VALUE(SUBSTITUTE(base,"","",""."")))), tSec, IF(ISNUMBER(t), IF(t<1, t*86400, t), "&" IF(REGEXMATCH(t,"":""), VALUE(LEFT(t, FIND("":"",t)-1))*60 + VALUE(MID(t, FIND("":"",t)+1, 99)), VALUE(SUBSTITUTE(t,"","",""."")))), INT(1000*(baseSec/tSec)^3) )"),601.0) | P6: =A11 | Q6: =B11 | R6: =C11 | S6: =M11 | T6: =N11
A7: F | B7: 100 Back | C7: 15 | D7: 3 | E7: 1:03.66 | F7: =IFERROR(__xludf.DUMMYFUNCTION("IF( REGEXMATCH(E7, "":""), 60*VALUE(INDEX(SPLIT(E7, "":""),1,1)) + VALUE(INDEX(SPLIT(E7, "":""),1,2)), VALUE(E7) )"),63.66) | G7: =average(F3-F5,F4-F6) | H7: 1.54 | I7: =C2 | J7: =C19 | K7: {=INDEX('Podium Target Times'!$C:$C, MATCH(A7&B7, 'Podium Target Times'!$A:$A&'Podium Target Times'!$B:$B, 0))} | L7: =L8+G8 | M7: =IF(L7<60, TEXT(L7,"0.00"), IF(L7<600, TEXT(L7/86400,"m:ss.00"), TEXT(L7/86400,"mm:ss.00"))) | N7: =IFERROR(__xludf.DUMMYFUNCTION("LET( gen,$A7, ev,$B7, t,$M7, hdrs, ARRAYFORMULA(UPPER(TRIM(CLEAN(SUBSTITUTE('AQUA POINTS'!$1:$1,CHAR(160),"" ""))))), col, MATCH(UPPER(ev), hdrs, 0), base, INDEX('AQUA POINTS'!$1:$3, IF(gen=""M"",2,3), col), baseSec, IF(ISNUMBER(base), IF(base<"&"1, base*86400, base), IF(REGEXMATCH(base,"":""), VALUE(LEFT(base, FIND("":"",base)-1))*60 + VALUE(MID(base, FIND("":"",base)+1, 99)), VALUE(SUBSTITUTE(base,"","",""."")))), tSec, IF(ISNUMBER(t), IF(t<1, t*86400, t), "&" IF(REGEXMATCH(t,"":""), VALUE(LEFT(t, FIND("":"",t)-1))*60 + VALUE(MID(t, FIND("":"",t)+1, 99)), VALUE(SUBSTITUTE(t,"","",""."")))), INT(1000*(baseSec/tSec)^3) )"),601.0) | P7: =A14 | Q7: =B14 | R7: =C14 | S7: =M14 | T7: =N14
A8: F | B8: 100 Back | C8: 16 | D8: 1 | E8: 1:01.22 | F8: =IFERROR(__xludf.DUMMYFUNCTION("IF( REGEXMATCH(E8, "":""), 60*VALUE(INDEX(SPLIT(E8, "":""),1,1)) + VALUE(INDEX(SPLIT(E8, "":""),1,2)), VALUE(E8) )"),61.22) | G8: =average(F5-F8,F6-F9,F7-F10) | H8: 1.1333333 | I8: =C2 | J8: =C19 | K8: {=INDEX('Podium Target Times'!$C:$C, MATCH(A8&B8, 'Podium Target Times'!$A:$A&'Podium Target Times'!$B:$B, 0))} | L8: =L11+G11 | M8: =IF(L8<60, TEXT(L8,"0.00"), IF(L8<600, TEXT(L8/86400,"m:ss.00"), TEXT(L8/86400,"mm:ss.00"))) | N8: =IFERROR(__xludf.DUMMYFUNCTION("LET( gen,$A8, ev,$B8, t,$M8, hdrs, ARRAYFORMULA(UPPER(TRIM(CLEAN(SUBSTITUTE('AQUA POINTS'!$1:$1,CHAR(160),"" ""))))), col, MATCH(UPPER(ev), hdrs, 0), base, INDEX('AQUA POINTS'!$1:$3, IF(gen=""M"",2,3), col), baseSec, IF(ISNUMBER(base), IF(base<"&"1, base*86400, base), IF(REGEXMATCH(base,"":""), VALUE(LEFT(base, FIND("":"",base)-1))*60 + VALUE(MID(base, FIND("":"",base)+1, 99)), VALUE(SUBSTITUTE(base,"","",""."")))), tSec, IF(ISNUMBER(t), IF(t<1, t*86400, t), "&" IF(REGEXMATCH(t,"":""), VALUE(LEFT(t, FIND("":"",t)-1))*60 + VALUE(MID(t, FIND("":"",t)+1, 99)), VALUE(SUBSTITUTE(t,"","",""."")))), INT(1000*(baseSec/tSec)^3) )"),632.0) | P8: =A16 | Q8: =B16 | R8: =C16 | S8: =M16 | T8: =N16
A9: F | B9: 100 Back | C9: 16 | D9: 2 | E9: 1:02.06 | F9: =IFERROR(__xludf.DUMMYFUNCTION("IF( REGEXMATCH(E9, "":""), 60*VALUE(INDEX(SPLIT(E9, "":""),1,1)) + VALUE(INDEX(SPLIT(E9, "":""),1,2)), VALUE(E9) )"),62.06) | G9: =average(F5-F8,F6-F9,F7-F10) | H9: 1.1333333 | I9: =C2 | J9: =C19 | K9: {=INDEX('Podium Target Times'!$C:$C, MATCH(A9&B9, 'Podium Target Times'!$A:$A&'Podium Target Times'!$B:$B, 0))} | L9: =L11+G11 | M9: =IF(L9<60, TEXT(L9,"0.00"), IF(L9<600, TEXT(L9/86400,"m:ss.00"), TEXT(L9/86400,"mm:ss.00"))) | N9: =IFERROR(__xludf.DUMMYFUNCTION("LET( gen,$A9, ev,$B9, t,$M9, hdrs, ARRAYFORMULA(UPPER(TRIM(CLEAN(SUBSTITUTE('AQUA POINTS'!$1:$1,CHAR(160),"" ""))))), col, MATCH(UPPER(ev), hdrs, 0), base, INDEX('AQUA POINTS'!$1:$3, IF(gen=""M"",2,3), col), baseSec, IF(ISNUMBER(base), IF(base<"&"1, base*86400, base), IF(REGEXMATCH(base,"":""), VALUE(LEFT(base, FIND("":"",base)-1))*60 + VALUE(MID(base, FIND("":"",base)+1, 99)), VALUE(SUBSTITUTE(base,"","",""."")))), tSec, IF(ISNUMBER(t), IF(t<1, t*86400, t), "&" IF(REGEXMATCH(t,"":""), VALUE(LEFT(t, FIND("":"",t)-1))*60 + VALUE(MID(t, FIND("":"",t)+1, 99)), VALUE(SUBSTITUTE(t,"","",""."")))), INT(1000*(baseSec/tSec)^3) )"),632.0) | P9: =A18 | Q9: =B18 | R9: =C18 | S9: =M18 | T9: =N18
A10: F | B10: 100 Back | C10: 16 | D10: 3 | E10: 1:02.52 | F10: =IFERROR(__xludf.DUMMYFUNCTION("IF( REGEXMATCH(E10, "":""), 60*VALUE(INDEX(SPLIT(E10, "":""),1,1)) + VALUE(INDEX(SPLIT(E10, "":""),1,2)), VALUE(E10) )"),62.52) | G10: =average(F5-F8,F6-F9,F7-F10) | H10: 1.1333333 | I10: =C2 | J10: =C19 | K10: {=INDEX('Podium Target Times'!$C:$C, MATCH(A10&B10, 'Podium Target Times'!$A:$A&'Podium Target Times'!$B:$B, 0))} | L10: =L11+G11 | M10: =IF(L10<60, TEXT(L10,"0.00"), IF(L10<600, TEXT(L10/86400,"m:ss.00"), TEXT(L10/86400,"mm:ss.00"))) | N10: =IFERROR(__xludf.DUMMYFUNCTION("LET( gen,$A10, ev,$B10, t,$M10, hdrs, ARRAYFORMULA(UPPER(TRIM(CLEAN(SUBSTITUTE('AQUA POINTS'!$1:$1,CHAR(160),"" ""))))), col, MATCH(UPPER(ev), hdrs, 0), base, INDEX('AQUA POINTS'!$1:$3, IF(gen=""M"",2,3), col), baseSec, IF(ISNUMBER(base), IF(ba"&"se<1, base*86400, base), IF(REGEXMATCH(base,"":""), VALUE(LEFT(base, FIND("":"",base)-1))*60 + VALUE(MID(base, FIND("":"",base)+1, 99)), VALUE(SUBSTITUTE(base,"","",""."")))), tSec, IF(ISNUMBER(t), IF(t<1, t*86400, t), "&" IF(REGEXMATCH(t,"":""), VALUE(LEFT(t, FIND("":"",t)-1))*60 + VALUE(MID(t, FIND("":"",t)+1, 99)), VALUE(SUBSTITUTE(t,"","",""."")))), INT(1000*(baseSec/tSec)^3) )"),632.0) | P10: =A19 | Q10: =B19 | R10: =C19 | S10: =M19 | T10: =N19
A11: F | B11: 100 Back | C11: 17 | D11: 1 | E11: 1:00.46 | F11: =IFERROR(__xludf.DUMMYFUNCTION("IF( REGEXMATCH(E11, "":""), 60*VALUE(INDEX(SPLIT(E11, "":""),1,1)) + VALUE(INDEX(SPLIT(E11, "":""),1,2)), VALUE(E11) )"),60.46) | G11: =average(F8-F11,F9-F12,F10-F13) | H11: 0.77 | I11: =C2 | J11: =C19 | K11: {=INDEX('Podium Target Times'!$C:$C, MATCH(A11&B11, 'Podium Target Times'!$A:$A&'Podium Target Times'!$B:$B, 0))} | L11: =L14+G14 | M11: =IF(L11<60, TEXT(L11,"0.00"), IF(L11<600, TEXT(L11/86400,"m:ss.00"), TEXT(L11/86400,"mm:ss.00"))) | N11: =IFERROR(__xludf.DUMMYFUNCTION("LET( gen,$A11, ev,$B11, t,$M11, hdrs, ARRAYFORMULA(UPPER(TRIM(CLEAN(SUBSTITUTE('AQUA POINTS'!$1:$1,CHAR(160),"" ""))))), col, MATCH(UPPER(ev), hdrs, 0), base, INDEX('AQUA POINTS'!$1:$3, IF(gen=""M"",2,3), col), baseSec, IF(ISNUMBER(base), IF(ba"&"se<1, base*86400, base), IF(REGEXMATCH(base,"":""), VALUE(LEFT(base, FIND("":"",base)-1))*60 + VALUE(MID(base, FIND("":"",base)+1, 99)), VALUE(SUBSTITUTE(base,"","",""."")))), tSec, IF(ISNUMBER(t), IF(t<1, t*86400, t), "&" IF(REGEXMATCH(t,"":""), VALUE(LEFT(t, FIND("":"",t)-1))*60 + VALUE(MID(t, FIND("":"",t)+1, 99)), VALUE(SUBSTITUTE(t,"","",""."")))), INT(1000*(baseSec/tSec)^3) )"),654.0) | P11: =P10 | Q11: =Q10 | R11: =R10+1 | S11: =M20 | T11: =N20
