Workbook

Sheet MOT Tables 25
A1: Gender | B1: Event | C1: Age | D1: Canada Track | E1: Canada Track Time | F1: Canada Track Time in Seconds | G1: Average Progression Delta | H1: Average Progression Delta VALUE ONLY | I1: Canada Entry Age | J1: Canada Arrival Age | K1: Malaysia Arrival Time (SEA BRONZE) | L1: Malaysia Track Time in Seconds | M1: Malaysia Track Time | N1: Malaysia Track AQUA
A2: F | B2: 100 Back | C2: 13 | D2: 1 | E2: 1:05.85 | F2: =IFERROR(__xludf.DUMMYFUNCTION("IF( REGEXMATCH(E2, "":""), 60*VALUE(INDEX(SPLIT(E2, "":""),1,1)) + VALUE(INDEX(SPLIT(E2, "":""),1,2)), VALUE(E2) )"),65.85) -> 65.85 | G2: 0 | H2: 0 | I2: =C2 -> 13 | J2: =C19 -> 21 | K2: {=INDEX('Podium Target Times'!$C:$C, MATCH(A2&B2, 'Podium Target Times'!$A:$A&'Podium Target Times'!$B:$B, 0))} -> 63.71 | L2: =L3+G3 -> 71.208333 | M2: =IF(L2<60, TEXT(L2,"0.00"), IF(L2<600, TEXT(L2/86400,"m:ss.00"), TEXT(L2/86400,"mm:ss.00"))) -> 1:11.21 | N2: =IFERROR(__xludf.DUMMYFUNCTION("LET( gen,$A2, ev,$B2, t,$M2, hdrs, ARRAYFORMULA(UPPER(TRIM(CLEAN(SUBSTITUTE('AQUA POINTS'!$1:$1,CHAR(160),"" ""))))), col, MATCH(UPPER(ev), hdrs, 0), base, INDEX('AQUA POINTS'!$1:$3, IF(gen=""M"",2,3), col), baseSec, IF(ISNUMBER(base), IF(base<"&"1, base*86400, base), IF(REGEXMATCH(base,"":""), VALUE(LEFT(base, FIND("":"",base)-1))*60 + VALUE(MID(base, FIND("":"",base)+1, 99)), VALUE(SUBSTITUTE(base,"","",""."")))), tSec, IF(ISNUMBER(t), IF(t<1, t*86400, t), "&" IF(REGEXMATCH(t,"":""), VALUE(LEFT(t, FIND("":"",t)-1))*60 + VALUE(MID(t, FIND("":"",t)+1, 99)), VALUE(SUBSTITUTE(t,"","",""."")))), INT(1000*(baseSec/tSec)^3) )"),516.0) -> 516
A3: F | B3: 100 Back | C3: 14 | D3: 1 | E3: 1:03.87 | F3: =IFERROR(__xludf.DUMMYFUNCTION("IF( REGEXMATCH(E3, "":""), 60*VALUE(INDEX(SPLIT(E3, "":""),1,1)) + VALUE(INDEX(SPLIT(E3, "":""),1,2)), VALUE(E3) )"),63.87) -> 63.87 | G3: =F2-F3 -> 1.98 | H3: 1.98 | I3: =C2 -> 13 | J3: =C19 -> 21 | K3: {=INDEX('Podium Target Times'!$C:$C, MATCH(A3&B3, 'Podium Target Times'!$A:$A&'Podium Target Times'!$B:$B, 0))} -> 63.71 | L3: =L5+G5 -> 69.228333 | M3: =IF(L3<60, TEXT(L3,"0.00"), IF(L3<600, TEXT(L3/86400,"m:ss.00"), TEXT(L3/86400,"mm:ss.00"))) -> 1:09.23 | N3: =IFERROR(__xludf.DUMMYFUNCTION("LET( gen,$A3, ev,$B3, t,$M3, hdrs, ARRAYFORMULA(UPPER(TRIM(CLEAN(SUBSTITUTE('AQUA POINTS'!$1:$1,CHAR(160),"" ""))))), col, MATCH(UPPER(ev), hdrs, 0), base, INDEX('AQUA POINTS'!$1:$3, IF(gen=""M"",2,3), col), baseSec, IF(ISNUMBER(base), IF(base<"&"1, base*86400, base), IF(REGEXMATCH(base,"":""), VALUE(LEFT(base, FIND("":"",base)-1))*60 + VALUE(MID(base, FIND("":"",base)+1, 99)), VALUE(SUBSTITUTE(base,"","",""."")))), tSec, IF(ISNUMBER(t), IF(t<1, t*86400, t), "&" IF(REGEXMATCH(t,"":""), VALUE(LEFT(t, FIND("":"",t)-1))*60 + VALUE(MID(t, FIND("":"",t)+1, 99)), VALUE(SUBSTITUTE(t,"","",""."")))), INT(1000*(baseSec/tSec)^3) )"),561.0) -> 561
A4: F | B4: 100 Back | C4: 14 | D4: 2 | E4: 1:04.75 | F4: =IFERROR(__xludf.DUMMYFUNCTION("IF( REGEXMATCH(E4, "":""), 60*VALUE(INDEX(SPLIT(E4, "":""),1,1)) + VALUE(INDEX(SPLIT(E4, "":""),1,2)), VALUE(E4) )"),64.75) -> 64.75 | G4: =F2-F3 -> 1.98 | H4: 1.98 | I4: =C2 -> 13 | J4: =C19 -> 21 | K4: {=INDEX('Podium Target Times'!$C:$C, MATCH(A4&B4, 'Podium Target Times'!$A:$A&'Podium Target Times'!$B:$B, 0))} -> 63.71 | L4: =L5+G5 -> 69.228333 | M4: =IF(L4<60, TEXT(L4,"0.00"), IF(L4<600, TEXT(L4/86400,"m:ss.00"), TEXT(L4/86400,"mm:ss.00"))) -> 1:09.23 | N4: =IFERROR(__xludf.DUMMYFUNCTION("LET( gen,$A4, ev,$B4, t,$M4, hdrs, ARRAYFORMULA(UPPER(TRIM(CLEAN(SUBSTITUTE('AQUA POINTS'!$1:$1,CHAR(160),"" ""))))), col, MATCH(UPPER(ev), hdrs, 0), base, INDEX('AQUA POINTS'!$1:$3, IF(gen=""M"",2,3), col), baseSec, IF(ISNUMBER(base), IF(base<"&"1, base*86400, base), IF(REGEXMATCH(base,"":""), VALUE(LEFT(base, FIND("":"",base)-1))*60 + VALUE(MID(base, FIND("":"",base)+1, 99)), VALUE(SUBSTITUTE(base,"","",""."")))), tSec, IF(ISNUMBER(t), IF(t<1, t*86400, t), "&" IF(REGEXMATCH(t,"":""), VALUE(LEFT(t, FIND("":"",t)-1))*60 + VALUE(MID(t, FIND("":"",t)+1, 99)), VALUE(SUBSTITUTE(t,"","",""."")))), INT(1000*(baseSec/tSec)^3) )"),561.0) -> 561
A5: F | B5: 100 Back | C5: 15 | D5: 1 | E5: 1:02.34 | F5: =IFERROR(__xludf.DUMMYFUNCTION("IF( REGEXMATCH(E5, "":""), 60*VALUE(INDEX(SPLIT(E5, "":""),1,1)) + VALUE(INDEX(SPLIT(E5, "":""),1,2)), VALUE(E5) )"),62.34) -> 62.34 | G5: =average(F3-F5,F4-F6) -> 1.54 | H5: 1.54 | I5: =C2 -> 13 | J5: =C19 -> 21 | K5: {=INDEX('Podium Target Times'!$C:$C, MATCH(A5&B5, 'Podium Target Times'!$A:$A&'Podium Target Times'!$B:$B, 0))} -> 63.71 | L5: =L8+G8 -> 67.688333 | M5: =IF(L5<60, TEXT(L5,"0.00"), IF(L5<600, TEXT(L5/86400,"m:ss.00"), TEXT(L5/86400,"mm:ss.00"))) -> 1:07.69 | N5: =IFERROR(__xludf.DUMMYFUNCTION("LET( gen,$A5, ev,$B5, t,$M5, hdrs, ARRAYFORMULA(UPPER(TRIM(CLEAN(SUBSTITUTE('AQUA POINTS'!$1:$1,CHAR(160),"" ""))))), col, MATCH(UPPER(ev), hdrs, 0), base, INDEX('AQUA POINTS'!$1:$3, IF(gen=""M"",2,3), col), baseSec, IF(ISNUMBER(base), IF(base<"&"1, base*86400, base), IF(REGEXMATCH(base,"":""), VALUE(LEFT(base, FIND("":"",base)-1))*60 + VALUE(MID(base, FIND("":"",base)+1, 99)), VALUE(SUBSTITUTE(base,"","",""."")))), tSec, IF(ISNUMBER(t), IF(t<1, t*86400, t), "&" IF(REGEXMATCH(t,"":""), VALUE(LEFT(t, FIND("":"",t)-1))*60 + VALUE(MID(t, FIND("":"",t)+1, 99)), VALUE(SUBSTITUTE(t,"","",""."")))), INT(1000*(baseSec/tSec)^3) )"),601.0) -> 601
A6: F | B6: 100 Back | C6: 15 | D6: 2 | E6: 1:03.20 | F6: =IFERROR(__xludf.DUMMYFUNCTION("IF( REGEXMATCH(E6, "":""), 60*VALUE(INDEX(SPLIT(E6, "":""),1,1)) + VALUE(INDEX(SPLIT(E6, "":""),1,2)), VALUE(E6) )"),63.2) -> 63.2 | G6: =average(F3-F5,F4-F6) -> 1.54 | H6: 1.54 | I6: =C2 -> 13 | J6: =C19 -> 21 | K6: {=INDEX('Podium Target Times'!$C:$C, MATCH(A6&B6, 'Podium Target Times'!$A:$A&'Podium Target Times'!$B:$B, 0))} -> 63.71 | L6: =L8+G8 -> 67.688333 | M6: =IF(L6<60, TEXT(L6,"0.00"), IF(L6<600, TEXT(L6/86400,"m:ss.00"), TEXT(L6/86400,"mm:ss.00"))) -> 1:07.69 | N6: =IFERROR(__xludf.DUMMYFUNCTION("LET( gen,$A6, ev,$B6, t,$M6, hdrs, ARRAYFORMULA(UPPER(TRIM(CLEAN(SUBSTITUTE('AQUA POINTS'!$1:$1,CHAR(160),"" ""))))), col, MATCH(UPPER(ev), hdrs, 0), base, INDEX('AQUA POINTS'!$1:$3, IF(gen=""M"",2,3), col), baseSec, IF(ISNUMBER(base), IF(base<"&"1, base*86400, base), IF(REGEXMATCH(base,"":""), VALUE(LEFT(base, FIND("":"",base)-1))*60 + VALUE(MID(base, FIND("":"",base)+1, 99)), VALUE(SUBSTITUTE(base,"","",""."")))), tSec, IF(ISNUMBER(t), IF(t<1, t*86400, t), "&" IF(REGEXMATCH(t,"":""), VALUE(LEFT(t, FIND("":"",t)-1))*60 + VALUE(MID(t, FIND("":"",t)+1, 99)), VALUE(SUBSTITUTE(t,"","",""."")))), INT(1000*(baseSec/tSec)^3) )"),601.0) -> 601
A7: F | B7: 100 Back | C7: 15 | D7: 3 | E7: 1:03.66 | F7: =IFERROR(__xludf.DUMMYFUNCTION("IF( REGEXMATCH(E7, "":""), 60*VALUE(INDEX(SPLIT(E7, "":""),1,1)) + VALUE(INDEX(SPLIT(E7, "":""),1,2)), VALUE(E7) )"),63.66) -> 63.66 | G7: =average(F3-F5,F4-F6) -> 1.54 | H7: 1.54 | I7: =C2 -> 13 | J7: =C19 -> 21 | K7: {=INDEX('Podium Target Times'!$C:$C, MATCH(A7&B7, 'Podium Target Times'!$A:$A&'Podium Target Times'!$B:$B, 0))} -> 63.71 | L7: =L8+G8 -> 67.688333 | M7: =IF(L7<60, TEXT(L7,"0.00"), IF(L7<600, TEXT(L7/86400,"m:ss.00"), TEXT(L7/86400,"mm:ss.00"))) -> 1:07.69 | N7: =IFERROR(__xludf.DUMMYFUNCTION("LET( gen,$A7, ev,$B7, t,$M7, hdrs, ARRAYFORMULA(UPPER(TRIM(CLEAN(SUBSTITUTE('AQUA POINTS'!$1:$1,CHAR(160),"" ""))))), col, MATCH(UPPER(ev), hdrs, 0), base, INDEX('AQUA POINTS'!$1:$3, IF(gen=""M"",2,3), col), baseSec, IF(ISNUMBER(base), IF(base<"&"1, base*86400, base), IF(REGEXMATCH(base,"":""), VALUE(LEFT(base, FIND("":"",base)-1))*60 + VALUE(MID(base, FIND("":"",base)+1, 99)), VALUE(SUBSTITUTE(base,"","",""."")))), tSec, IF(ISNUMBER(t), IF(t<1, t*86400, t), "&" IF(REGEXMATCH(t,"":""), VALUE(LEFT(t, FIND("":"",t)-1))*60 + VALUE(MID(t, FIND("":"",t)+1, 99)), VALUE(SUBSTITUTE(t,"","",""."")))), INT(1000*(baseSec/tSec)^3) )"),601.0) -> 601
A8: F | B8: 100 Back | C8: 16 | D8: 1 | E8: 1:01.22 | F8: =IFERROR(__xludf.DUMMYFUNCTION("IF( REGEXMATCH(E8, "":""), 60*VALUE(INDEX(SPLIT(E8, "":""),1,1)) + VALUE(INDEX(SPLIT(E8, "":""),1,2)), VALUE(E8) )"),61.22) -> 61.22 | G8: =average(F5-F8,F6-F9,F7-F10) -> 1.1333333 | H8: 1.1333333 | I8: =C2 -> 13 | J8: =C19 -> 21 | K8: {=INDEX('Podium Target Times'!$C:$C, MATCH(A8&B8, 'Podium Target Times'!$A:$A&'Podium Target Times'!$B:$B, 0))} -> 63.71 | L8: =L11+G11 -> 66.555 | M8: =IF(L8<60, TEXT(L8,"0.00"), IF(L8<600, TEXT(L8/86400,"m:ss.00"), TEXT(L8/86400,"mm:ss.00"))) -> 1:06.56 | N8: =IFERROR(__xludf.DUMMYFUNCTION("LET( gen,$A8, ev,$B8, t,$M8, hdrs, ARRAYFORMULA(UPPER(TRIM(CLEAN(SUBSTITUTE('AQUA POINTS'!$1:$1,CHAR(160),"" ""))))), col, MATCH(UPPER(ev), hdrs, 0), base, INDEX('AQUA POINTS'!$1:$3, IF(gen=""M"",2,3), col), baseSec, IF(ISNUMBER(base), IF(base<"&"1, base*86400, base), IF(REGEXMATCH(base,"":""), VALUE(LEFT(base, FIND("":"",base)-1))*60 + VALUE(MID(base, FIND("":"",base)+1, 99)), VALUE(SUBSTITUTE(base,"","",""."")))), tSec, IF(ISNUMBER(t), IF(t<1, t*86400, t), "&" IF(REGEXMATCH(t,"":""), VALUE(LEFT(t, FIND("":"",t)-1))*60 + VALUE(MID(t, FIND("":"",t)+1, 99)), VALUE(SUBSTITUTE(t,"","",""."")))), INT(1000*(baseSec/tSec)^3) )"),632.0) -> 632
A9: F | B9: 100 Back | C9: 16 | D9: 2 | E9: 1:02.06 | F9: =IFERROR(__xludf.DUMMYFUNCTION("IF( REGEXMATCH(E9, "":""), 60*VALUE(INDEX(SPLIT(E9, "":""),1,1)) + VALUE(INDEX(SPLIT(E9, "":""),1,2)), VALUE(E9) )"),62.06) -> 62.06 | G9: =average(F5-F8,F6-F9,F7-F10) -> 1.1333333 | H9: 1.1333333 | I9: =C2 -> 13 | J9: =C19 -> 21 | K9: {=INDEX('Podium Target Times'!$C:$C, MATCH(A9&B9, 'Podium Target Times'!$A:$A&'Podium Target Times'!$B:$B, 0))} -> 63.71 | L9: =L11+G11 -> 66.555 | M9: =IF(L9<60, TEXT(L9,"0.00"), IF(L9<600, TEXT(L9/86400,"m:ss.00"), TEXT(L9/86400,"mm:ss.00"))) -> 1:06.56 | N9: =IFERROR(__xludf.DUMMYFUNCTION("LET( gen,$A9, ev,$B9, t,$M9, hdrs, ARRAYFORMULA(UPPER(TRIM(CLEAN(SUBSTITUTE('AQUA POINTS'!$1:$1,CHAR(160),"" ""))))), col, MATCH(UPPER(ev), hdrs, 0), base, INDEX('AQUA POINTS'!$1:$3, IF(gen=""M"",2,3), col), baseSec, IF(ISNUMBER(base), IF(base<"&"1, base*86400, base), IF(REGEXMATCH(base,"":""), VALUE(LEFT(base, FIND("":"",base)-1))*60 + VALUE(MID(base, FIND("":"",base)+1, 99)), VALUE(SUBSTITUTE(base,"","",""."")))), tSec, IF(ISNUMBER(t), IF(t<1, t*86400, t), "&" IF(REGEXMATCH(t,"":""), VALUE(LEFT(t, FIND("":"",t)-1))*60 + VALUE(MID(t, FIND("":"",t)+1, 99)), VALUE(SUBSTITUTE(t,"","",""."")))), INT(1000*(baseSec/tSec)^3) )"),632.0) -> 632
A10: F | B10: 100 Back | C10: 16 | D10: 3 | E10: 1:02.52 | F10: =IFERROR(__xludf.DUMMYFUNCTION("IF( REGEXMATCH(E10, "":""), 60*VALUE(INDEX(SPLIT(E10, "":""),1,1)) + VALUE(INDEX(SPLIT(E10, "":""),1,2)), VALUE(E10) )"),62.52) -> 62.52 | G10: =average(F5-F8,F6-F9,F7-F10) -> 1.1333333 | H10: 1.1333333 | I10: =C2 -> 13 | J10: =C19 -> 21 | K10: {=INDEX('Podium Target Times'!$C:$C, MATCH(A10&B10, 'Podium Target Times'!$A:$A&'Podium Target Times'!$B:$B, 0))} -> 63.71 | L10: =L11+G11 -> 66.555 | M10: =IF(L10<60, TEXT(L10,"0.00"), IF(L10<600, TEXT(L10/86400,"m:ss.00"), TEXT(L10/86400,"mm:ss.00"))) -> 1:06.56 | N10: =IFERROR(__xludf.DUMMYFUNCTION("LET( gen,$A10, ev,$B10, t,$M10, hdrs, ARRAYFORMULA(UPPER(TRIM(CLEAN(SUBSTITUTE('AQUA POINTS'!$1:$1,CHAR(160),"" ""))))), col, MATCH(UPPER(ev), hdrs, 0), base, INDEX('AQUA POINTS'!$1:$3, IF(gen=""M"",2,3), col), baseSec, IF(ISNUMBER(base), IF(ba"&"se<1, base*86400, base), IF(REGEXMATCH(base,"":""), VALUE(LEFT(base, FIND("":"",base)-1))*60 + VALUE(MID(base, FIND("":"",base)+1, 99)), VALUE(SUBSTITUTE(base,"","",""."")))), tSec, IF(ISNUMBER(t), IF(t<1, t*86400, t), "&" IF(REGEXMATCH(t,"":""), VALUE(LEFT(t, FIND("":"",t)-1))*60 + VALUE(MID(t, FIND("":"",t)+1, 99)), VALUE(SUBSTITUTE(t,"","",""."")))), INT(1000*(baseSec/tSec)^3) )"),632.0) -> 632
A11: F | B11: 100 Back | C11: 17 | D11: 1 | E11: 1:00.46 | F11: =IFERROR(__xludf.DUMMYFUNCTION("IF( REGEXMATCH(E11, "":""), 60*VALUE(INDEX(SPLIT(E11, "":""),1,1)) + VALUE(INDEX(SPLIT(E11, "":""),1,2)), VALUE(E11) )"),60.46) -> 60.46 | G11: =average(F8-F11,F9-F12,F10-F13) -> 0.77 | H11: 0.77 | I11: =C2 -> 13 | J11: =C19 -> 21 | K11: {=INDEX('Podium Target Times'!$C:$C, MATCH(A11&B11, 'Podium Target Times'!$A:$A&'Podium Target Times'!$B:$B, 0))} -> 63.71 | L11: =L14+G14 -> 65.785 | M11: =IF(L11<60, TEXT(L11,"0.00"), IF(L11<600, TEXT(L11/86400,"m:ss.00"), TEXT(L11/86400,"mm:ss.00"))) -> 1:05.79 | N11: =IFERROR(__xludf.DUMMYFUNCTION("LET( gen,$A11, ev,$B11, t,$M11, hdrs, ARRAYFORMULA(UPPER(TRIM(CLEAN(SUBSTITUTE('AQUA POINTS'!$1:$1,CHAR(160),"" ""))))), col, MATCH(UPPER(ev), hdrs, 0), base, INDEX('AQUA POINTS'!$1:$3, IF(gen=""M"",2,3), col), baseSec, IF(ISNUMBER(base), IF(ba"&"se<1, base*86400, base), IF(REGEXMATCH(base,"":""), VALUE(LEFT(base, FIND("":"",base)-1))*60 + VALUE(MID(base, FIND("":"",base)+1, 99)), VALUE(SUBSTITUTE(base,"","",""."")))), tSec, IF(ISNUMBER(t), IF(t<1, t*86400, t), "&" IF(REGEXMATCH(t,"":""), VALUE(LEFT(t, FIND("":"",t)-1))*60 + VALUE(MID(t, FIND("":"",t)+1, 99)), VALUE(SUBSTITUTE(t,"","",""."")))), INT(1000*(baseSec/tSec)^3) )"),654.0) -> 654
A12: F | B12: 100 Back | C12: 17 | D12: 2 | E12: 1:01.29 | F12: =IFERROR(__xludf.DUMMYFUNCTION("IF( REGEXMATCH(E12, "":""), 60*VALUE(INDEX(SPLIT(E12, "":""),1,1)) + VALUE(INDEX(SPLIT(E12, "":""),1,2)), VALUE(E12) )"),61.29) -> 61.29 | G12: =average(F8-F11,F9-F12,F10-F13) -> 0.77 | H12: 0.77 | I12: =C2 -> 13 | J12: =C19 -> 21 | K12: {=INDEX('Podium Target Times'!$C:$C, MATCH(A12&B12, 'Podium Target Times'!$A:$A&'Podium Target Times'!$B:$B, 0))} -> 63.71 | L12: =L14+G14 -> 65.785 | M12: =IF(L12<60, TEXT(L12,"0.00"), IF(L12<600, TEXT(L12/86400,"m:ss.00"), TEXT(L12/86400,"mm:ss.00"))) -> 1:05.79 | N12: =IFERROR(__xludf.DUMMYFUNCTION("LET( gen,$A12, ev,$B12, t,$M12, hdrs, ARRAYFORMULA(UPPER(TRIM(CLEAN(SUBSTITUTE('AQUA POINTS'!$1:$1,CHAR(160),"" ""))))), col, MATCH(UPPER(ev), hdrs, 0), base, INDEX('AQUA POINTS'!$1:$3, IF(gen=""M"",2,3), col), baseSec, IF(ISNUMBER(base), IF(ba"&"se<1, base*86400, base), IF(REGEXMATCH(base,"":""), VALUE(LEFT(base, FIND("":"",base)-1))*60 + VALUE(MID(base, FIND("":"",base)+1, 99)), VALUE(SUBSTITUTE(base,"","",""."")))), tSec, IF(ISNUMBER(t), IF(t<1, t*86400, t), "&" IF(REGEXMATCH(t,"":""), VALUE(LEFT(t, FIND("":"",t)-1))*60 + VALUE(MID(t, FIND("":"",t)+1, 99)), VALUE(SUBSTITUTE(t,"","",""."")))), INT(1000*(baseSec/tSec)^3) )"),654.0) -> 654
A13: F | B13: 100 Back | C13: 17 | D13: 3 | E13: 1:01.74 | F13: =IFERROR(__xludf.DUMMYFUNCTION("IF( REGEXMATCH(E13, "":""), 60*VALUE(INDEX(SPLIT(E13, "":""),1,1)) + VALUE(INDEX(SPLIT(E13, "":""),1,2)), VALUE(E13) )"),61.74) -> 61.74 | G13: =average(F8-F11,F9-F12,F10-F13) -> 0.77 | H13: 0.77 | I13: =C2 -> 13 | J13: =C19 -> 21 | K13: {=INDEX('Podium Target Times'!$C:$C, MATCH(A13&B13, 'Podium Target Times'!$A:$A&'Podium Target Times'!$B:$B, 0))} -> 63.71 | L13: =L14+G14 -> 65.785 | M13: =IF(L13<60, TEXT(L13,"0.00"), IF(L13<600, TEXT(L13/86400,"m:ss.00"), TEXT(L13/86400,"mm:ss.00"))) -> 1:05.79 | N13: =IFERROR(__xludf.DUMMYFUNCTION("LET( gen,$A13, ev,$B13, t,$M13, hdrs, ARRAYFORMULA(UPPER(TRIM(CLEAN(SUBSTITUTE('AQUA POINTS'!$1:$1,CHAR(160),"" ""))))), col, MATCH(UPPER(ev), hdrs, 0), base, INDEX('AQUA POINTS'!$1:$3, IF(gen=""M"",2,3), col), baseSec, IF(ISNUMBER(base), IF(ba"&"se<1, base*86400, base), IF(REGEXMATCH(base,"":""), VALUE(LEFT(base, FIND("":"",base)-1))*60 + VALUE(MID(base, FIND("":"",base)+1, 99)), VALUE(SUBSTITUTE(base,"","",""."")))), tSec, IF(ISNUMBER(t), IF(t<1, t*86400, t), "&" IF(REGEXMATCH(t,"":""), VALUE(LEFT(t, FIND("":"",t)-1))*60 + VALUE(MID(t, FIND("":"",t)+1, 99)), VALUE(SUBSTITUTE(t,"","",""."")))), INT(1000*(baseSec/tSec)^3) )"),654.0) -> 654
A14: F | B14: 100 Back | C14: 18 | D14: 2 | E14: 1:00.79 | F14: =IFERROR(__xludf.DUMMYFUNCTION("IF( REGEXMATCH(E14, "":""), 60*VALUE(INDEX(SPLIT(E14, "":""),1,1)) + VALUE(INDEX(SPLIT(E14, "":""),1,2)), VALUE(E14) )"),60.79) -> 60.79 | G14: =average(F12-F14,F13-F15) -> 0.505 | H14: 0.505 | I14: =C2 -> 13 | J14: =C19 -> 21 | K14: {=INDEX('Podium Target Times'!$C:$C, MATCH(A14&B14, 'Podium Target Times'!$A:$A&'Podium Target Times'!$B:$B, 0))} -> 63.71 | L14: =L16+G16 -> 65.28 | M14: =IF(L14<60, TEXT(L14,"0.00"), IF(L14<600, TEXT(L14/86400,"m:ss.00"), TEXT(L14/86400,"mm:ss.00"))) -> 1:05.28 | N14: =IFERROR(__xludf.DUMMYFUNCTION("LET( gen,$A14, ev,$B14, t,$M14, hdrs, ARRAYFORMULA(UPPER(TRIM(CLEAN(SUBSTITUTE('AQUA POINTS'!$1:$1,CHAR(160),"" ""))))), col, MATCH(UPPER(ev), hdrs, 0), base, INDEX('AQUA POINTS'!$1:$3, IF(gen=""M"",2,3), col), baseSec, IF(ISNUMBER(base), IF(ba"&"se<1, base*86400, base), IF(REGEXMATCH(base,"":""), VALUE(LEFT(base, FIND("":"",base)-1))*60 + VALUE(MID(base, FIND("":"",base)+1, 99)), VALUE(SUBSTITUTE(base,"","",""."")))), tSec, IF(ISNUMBER(t), IF(t<1, t*86400, t), "&" IF(REGEXMATCH(t,"":""), VALUE(LEFT(t, FIND("":"",t)-1))*60 + VALUE(MID(t, FIND("":"",t)+1, 99)), VALUE(SUBSTITUTE(t,"","",""."")))), INT(1000*(baseSec/tSec)^3) )"),670.0) -> 670
A15: F | B15: 100 Back | C15: 18 | D15: 3 | E15: 1:01.23 | F15: =IFERROR(__xludf.DUMMYFUNCTION("IF( REGEXMATCH(E15, "":""), 60*VALUE(INDEX(SPLIT(E15, "":""),1,1)) + VALUE(INDEX(SPLIT(E15, "":""),1,2)), VALUE(E15) )"),61.23) -> 61.23 | G15: =average(F12-F14,F13-F15) -> 0.505 | H15: 0.505 | I15: =C2 -> 13 | J15: =C19 -> 21 | K15: {=INDEX('Podium Target Times'!$C:$C, MATCH(A15&B15, 'Podium Target Times'!$A:$A&'Podium Target Times'!$B:$B, 0))} -> 63.71 | L15: =L16+G16 -> 65.28 | M15: =IF(L15<60, TEXT(L15,"0.00"), IF(L15<600, TEXT(L15/86400,"m:ss.00"), TEXT(L15/86400,"mm:ss.00"))) -> 1:05.28 | N15: =IFERROR(__xludf.DUMMYFUNCTION("LET( gen,$A15, ev,$B15, t,$M15, hdrs, ARRAYFORMULA(UPPER(TRIM(CLEAN(SUBSTITUTE('AQUA POINTS'!$1:$1,CHAR(160),"" ""))))), col, MATCH(UPPER(ev), hdrs, 0), base, INDEX('AQUA POINTS'!$1:$3, IF(gen=""M"",2,3), col), baseSec, IF(ISNUMBER(base), IF(ba"&"se<1, base*86400, base), IF(REGEXMATCH(base,"":""), VALUE(LEFT(base, FIND("":"",base)-1))*60 + VALUE(MID(base, FIND("":"",base)+1, 99)), VALUE(SUBSTITUTE(base,"","",""."")))), tSec, IF(ISNUMBER(t), IF(t<1, t*86400, t), "&" IF(REGEXMATCH(t,"":""), VALUE(LEFT(t, FIND("":"",t)-1))*60 + VALUE(MID(t, FIND("":"",t)+1, 99)), VALUE(SUBSTITUTE(t,"","",""."")))), INT(1000*(baseSec/tSec)^3) )"),670.0) -> 670
A16: F | B16: 100 Back | C16: 19 | D16: 2 | E16: 1:00.46 | F16: =IFERROR(__xludf.DUMMYFUNCTION("IF( REGEXMATCH(E16, "":""), 60*VALUE(INDEX(SPLIT(E16, "":""),1,1)) + VALUE(INDEX(SPLIT(E16, "":""),1,2)), VALUE(E16) )"),60.46) -> 60.46 | G16: =average(F14-F16,F15-F17) -> 0.33 | H16: 0.33 | I16: =C2 -> 13 | J16: =C19 -> 21 | K16: {=INDEX('Podium Target Times'!$C:$C, MATCH(A16&B16, 'Podium Target Times'!$A:$A&'Podium Target Times'!$B:$B, 0))} -> 63.71 | L16: =L18+G18 -> 64.95 | M16: =IF(L16<60, TEXT(L16,"0.00"), IF(L16<600, TEXT(L16/86400,"m:ss.00"), TEXT(L16/86400,"mm:ss.00"))) -> 1:04.95 | N16: =IFERROR(__xludf.DUMMYFUNCTION("LET( gen,$A16, ev,$B16, t,$M16, hdrs, ARRAYFORMULA(UPPER(TRIM(CLEAN(SUBSTITUTE('AQUA POINTS'!$1:$1,CHAR(160),"" ""))))), col, MATCH(UPPER(ev), hdrs, 0), base, INDEX('AQUA POINTS'!$1:$3, IF(gen=""M"",2,3), col), baseSec, IF(ISNUMBER(base), IF(ba"&"se<1, base*86400, base), IF(REGEXMATCH(base,"":""), VALUE(LEFT(base, FIND("":"",base)-1))*60 + VALUE(MID(base, FIND("":"",base)+1, 99)), VALUE(SUBSTITUTE(base,"","",""."")))), tSec, IF(ISNUMBER(t), IF(t<1, t*86400, t), "&" IF(REGEXMATCH(t,"":""), VALUE(LEFT(t, FIND("":"",t)-1))*60 + VALUE(MID(t, FIND("":"",t)+1, 99)), VALUE(SUBSTITUTE(t,"","",""."")))), INT(1000*(baseSec/tSec)^3) )"),680.0) -> 680
A17: F | B17: 100 Back | C17: 19 | D17: 3 | E17: 1:00.90 | F17: =IFERROR(__xludf.DUMMYFUNCTION("IF( REGEXMATCH(E17, "":""), 60*VALUE(INDEX(SPLIT(E17, "":""),1,1)) + VALUE(INDEX(SPLIT(E17, "":""),1,2)), VALUE(E17) )"),60.9) -> 60.9 | G17: =average(F14-F16,F15-F17) -> 0.33 | H17: 0.33 | I17: =C2 -> 13 | J17: =C19 -> 21 | K17: {=INDEX('Podium Target Times'!$C:$C, MATCH(A17&B17, 'Podium Target Times'!$A:$A&'Podium Target Times'!$B:$B, 0))} -> 63.71 | L17: =L18+G18 -> 64.95 | M17: =IF(L17<60, TEXT(L17,"0.00"), IF(L17<600, TEXT(L17/86400,"m:ss.00"), TEXT(L17/86400,"mm:ss.00"))) -> 1:04.95 | N17: =IFERROR(__xludf.DUMMYFUNCTION("LET( gen,$A17, ev,$B17, t,$M17, hdrs, ARRAYFORMULA(UPPER(TRIM(CLEAN(SUBSTITUTE('AQUA POINTS'!$1:$1,CHAR(160),"" ""))))), col, MATCH(UPPER(ev), hdrs, 0), base, INDEX('AQUA POINTS'!$1:$3, IF(gen=""M"",2,3), col), baseSec, IF(ISNUMBER(base), IF(ba"&"se<1, base*86400, base), IF(REGEXMATCH(base,"":""), VALUE(LEFT(base, FIND("":"",base)-1))*60 + VALUE(MID(base, FIND("":"",base)+1, 99)), VALUE(SUBSTITUTE(base,"","",""."")))), tSec, IF(ISNUMBER(t), IF(t<1, t*86400, t), "&" IF(REGEXMATCH(t,"":""), VALUE(LEFT(t, FIND("":"",t)-1))*60 + VALUE(MID(t, FIND("":"",t)+1, 99)), VALUE(SUBSTITUTE(t,"","",""."")))), INT(1000*(baseSec/tSec)^3) )"),680.0) -> 680
A18: F | B18: 100 Back | C18: 20 | D18: 3 | E18: 1:00.66 | F18: =IFERROR(__xludf.DUMMYFUNCTION("IF( REGEXMATCH(E18, "":""), 60*VALUE(INDEX(SPLIT(E18, "":""),1,1)) + VALUE(INDEX(SPLIT(E18, "":""),1,2)), VALUE(E18) )"),60.66) -> 60.66 | G18: =F17-F18 -> 0.24 | H18: 0.24 | I18: =C2 -> 13 | J18: =C19 -> 21 | K18: {=INDEX('Podium Target Times'!$C:$C, MATCH(A18&B18, 'Podium Target Times'!$A:$A&'Podium Target Times'!$B:$B, 0))} -> 63.71 | L18: =L19+G19 -> 64.71 | M18: =IF(L18<60, TEXT(L18,"0.00"), IF(L18<600, TEXT(L18/86400,"m:ss.00"), TEXT(L18/86400,"mm:ss.00"))) -> 1:04.71 | N18: =IFERROR(__xludf.DUMMYFUNCTION("LET( gen,$A18, ev,$B18, t,$M18, hdrs, ARRAYFORMULA(UPPER(TRIM(CLEAN(SUBSTITUTE('AQUA POINTS'!$1:$1,CHAR(160),"" ""))))), col, MATCH(UPPER(ev), hdrs, 0), base, INDEX('AQUA POINTS'!$1:$3, IF(gen=""M"",2,3), col), baseSec, IF(ISNUMBER(base), IF(ba"&"se<1, base*86400, base), IF(REGEXMATCH(base,"":""), VALUE(LEFT(base, FIND("":"",base)-1))*60 + VALUE(MID(base, FIND("":"",base)+1, 99)), VALUE(SUBSTITUTE(base,"","",""."")))), tSec, IF(ISNUMBER(t), IF(t<1, t*86400, t), "&" IF(REGEXMATCH(t,"":""), VALUE(LEFT(t, FIND("":"",t)-1))*60 + VALUE(MID(t, FIND("":"",t)+1, 99)), VALUE(SUBSTITUTE(t,"","",""."")))), INT(1000*(baseSec/tSec)^3) )"),688.0) -> 688
A19: F | B19: 100 Back | C19: 21 | D19: 3 | E19: 1:00.46 | F19: =IFERROR(__xludf.DUMMYFUNCTION("IF( REGEXMATCH(E19, "":""), 60*VALUE(INDEX(SPLIT(E19, "":""),1,1)) + VALUE(INDEX(SPLIT(E19, "":""),1,2)), VALUE(E19) )"),60.46) -> 60.46 | G19: =F18-F19 -> 0.2 | H19: 0.2 | I19: =C2 -> 13 | J19: =C19 -> 21 | K19: {=INDEX('Podium Target Times'!$C:$C, MATCH(A19&B19, 'Podium Target Times'!$A:$A&'Podium Target Times'!$B:$B, 0))} -> 63.71 | L19: =G19+L20 -> 64.51 | M19: =IF(L19<60, TEXT(L19,"0.00"), IF(L19<600, TEXT(L19/86400,"m:ss.00"), TEXT(L19/86400,"mm:ss.00"))) -> 1:04.51 | N19: =IFERROR(__xludf.DUMMYFUNCTION("LET( gen,$A19, ev,$B19, t,$M19, hdrs, ARRAYFORMULA(UPPER(TRIM(CLEAN(SUBSTITUTE('AQUA POINTS'!$1:$1,CHAR(160),"" ""))))), col, MATCH(UPPER(ev), hdrs, 0), base, INDEX('AQUA POINTS'!$1:$3, IF(gen=""M"",2,3), col), baseSec, IF(ISNUMBER(base), IF(ba"&"se<1, base*86400, base), IF(REGEXMATCH(base,"":""), VALUE(LEFT(base, FIND("":"",base)-1))*60 + VALUE(MID(base, FIND("":"",base)+1, 99)), VALUE(SUBSTITUTE(base,"","",""."")))), tSec, IF(ISNUMBER(t), IF(t<1, t*86400, t), "&" IF(REGEXMATCH(t,"":""), VALUE(LEFT(t, FIND("":"",t)-1))*60 + VALUE(MID(t, FIND("":"",t)+1, 99)), VALUE(SUBSTITUTE(t,"","",""."")))), INT(1000*(baseSec/tSec)^3) )"),694.0) -> 694
A20: F | B20: 100 Back | C20: 22 | F20: =IFERROR(__xludf.DUMMYFUNCTION("IF( REGEXMATCH(E20, "":""), 60*VALUE(INDEX(SPLIT(E20, "":""),1,1)) + VALUE(INDEX(SPLIT(E20, "":""),1,2)), VALUE(E20) )"),0.0) -> 0 | I20: =C2 -> 13 | J20: =C19 -> 21 | K20: {=INDEX('Podium Target Times'!$C:$C, MATCH(A20&B20, 'Podium Target Times'!$A:$A&'Podium Target Times'!$B:$B, 0))} -> 63.71 | L20: =G19+L21 -> 64.31 | M20: =IF(L20<60, TEXT(L20,"0.00"), IF(L20<600, TEXT(L20/86400,"m:ss.00"), TEXT(L20/86400,"mm:ss.00"))) -> 1:04.31 | N20: =IFERROR(__xludf.DUMMYFUNCTION("LET( gen,$A20, ev,$B20, t,$M20, hdrs, ARRAYFORMULA(UPPER(TRIM(CLEAN(SUBSTITUTE('AQUA POINTS'!$1:$1,CHAR(160),"" ""))))), col, MATCH(UPPER(ev), hdrs, 0), base, INDEX('AQUA POINTS'!$1:$3, IF(gen=""M"",2,3), col), baseSec, IF(ISNUMBER(base), IF(ba"&"se<1, base*86400, base), IF(REGEXMATCH(base,"":""), VALUE(LEFT(base, FIND("":"",base)-1))*60 + VALUE(MID(base, FIND("":"",base)+1, 99)), VALUE(SUBSTITUTE(base,"","",""."")))), tSec, IF(ISNUMBER(t), IF(t<1, t*86400, t), "&" IF(REGEXMATCH(t,"":""), VALUE(LEFT(t, FIND("":"",t)-1))*60 + VALUE(MID(t, FIND("":"",t)+1, 99)), VALUE(SUBSTITUTE(t,"","",""."")))), INT(1000*(baseSec/tSec)^3) )"),701.0) -> 701
A21: F | B21: 100 Back | C21: 23 | F21: =IFERROR(__xludf.DUMMYFUNCTION("IF( REGEXMATCH(E21, "":""), 60*VALUE(INDEX(SPLIT(E21, "":""),1,1)) + VALUE(INDEX(SPLIT(E21, "":""),1,2)), VALUE(E21) )"),0.0) -> 0 | I21: =C2 -> 13 | J21: =C19 -> 21 | K21: {=INDEX('Podium Target Times'!$C:$C, MATCH(A21&B21, 'Podium Target Times'!$A:$A&'Podium Target Times'!$B:$B, 0))} -> 63.71 | L21: =L22+G19 -> 64.11 | M21: =IF(L21<60, TEXT(L21,"0.00"), IF(L21<600, TEXT(L21/86400,"m:ss.00"), TEXT(L21/86400,"mm:ss.00"))) -> 1:04.11 | N21: =IFERROR(__xludf.DUMMYFUNCTION("LET( gen,$A21, ev,$B21, t,$M21, hdrs, ARRAYFORMULA(UPPER(TRIM(CLEAN(SUBSTITUTE('AQUA POINTS'!$1:$1,CHAR(160),"" ""))))), col, MATCH(UPPER(ev), hdrs, 0), base, INDEX('AQUA POINTS'!$1:$3, IF(gen=""M"",2,3), col), baseSec, IF(ISNUMBER(base), IF(ba"&"se<1, base*86400, base), IF(REGEXMATCH(base,"":""), VALUE(LEFT(base, FIND("":"",base)-1))*60 + VALUE(MID(base, FIND("":"",base)+1, 99)), VALUE(SUBSTITUTE(base,"","",""."")))), tSec, IF(ISNUMBER(t), IF(t<1, t*86400, t), "&" IF(REGEXMATCH(t,"":""), VALUE(LEFT(t, FIND("":"",t)-1))*60 + VALUE(MID(t, FIND("":"",t)+1, 99)), VALUE(SUBSTITUTE(t,"","",""."")))), INT(1000*(baseSec/tSec)^3) )"),707.0) -> 707
A22: F | B22: 100 Back | C22: 24 | F22: =IFERROR(__xludf.DUMMYFUNCTION("IF( REGEXMATCH(E22, "":""), 60*VALUE(INDEX(SPLIT(E22, "":""),1,1)) + VALUE(INDEX(SPLIT(E22, "":""),1,2)), VALUE(E22) )"),0.0) -> 0 | I22: =C2 -> 13 | J22: =C19 -> 21 | K22: {=INDEX('Podium Target Times'!$C:$C, MATCH(A22&B22, 'Podium Target Times'!$A:$A&'Podium Target Times'!$B:$B, 0))} -> 63.71 | L22: =L23+G19 -> 63.91 | M22: =IF(L22<60, TEXT(L22,"0.00"), IF(L22<600, TEXT(L22/86400,"m:ss.00"), TEXT(L22/86400,"mm:ss.00"))) -> 1:03.91 | N22: =IFERROR(__xludf.DUMMYFUNCTION("LET( gen,$A22, ev,$B22, t,$M22, hdrs, ARRAYFORMULA(UPPER(TRIM(CLEAN(SUBSTITUTE('AQUA POINTS'!$1:$1,CHAR(160),"" ""))))), col, MATCH(UPPER(ev), hdrs, 0), base, INDEX('AQUA POINTS'!$1:$3, IF(gen=""M"",2,3), col), baseSec, IF(ISNUMBER(base), IF(ba"&"se<1, base*86400, base), IF(REGEXMATCH(base,"":""), VALUE(LEFT(base, FIND("":"",base)-1))*60 + VALUE(MID(base, FIND("":"",base)+1, 99)), VALUE(SUBSTITUTE(base,"","",""."")))), tSec, IF(ISNUMBER(t), IF(t<1, t*86400, t), "&" IF(REGEXMATCH(t,"":""), VALUE(LEFT(t, FIND("":"",t)-1))*60 + VALUE(MID(t, FIND("":"",t)+1, 99)), VALUE(SUBSTITUTE(t,"","",""."")))), INT(1000*(baseSec/tSec)^3) )"),714.0) -> 714
A23: F | B23: 100 Back | C23: 25 | F23: =IFERROR(__xludf.DUMMYFUNCTION("IF( REGEXMATCH(E23, "":""), 60*VALUE(INDEX(SPLIT(E23, "":""),1,1)) + VALUE(INDEX(SPLIT(E23, "":""),1,2)), VALUE(E23) )"),0.0) -> 0 | I23: =C2 -> 13 | J23: =C19 -> 21 | K23: {=INDEX('Podium Target Times'!$C:$C, MATCH(A23&B23, 'Podium Target Times'!$A:$A&'Podium Target Times'!$B:$B, 0))} -> 63.71 | L23: =K23 -> 63.71 | M23: =IF(L23<60, TEXT(L23,"0.00"), IF(L23<600, TEXT(L23/86400,"m:ss.00"), TEXT(L23/86400,"mm:ss.00"))) -> 1:03.71 | N23: =IFERROR(__xludf.DUMMYFUNCTION("LET( gen,$A23, ev,$B23, t,$M23, hdrs, ARRAYFORMULA(UPPER(TRIM(CLEAN(SUBSTITUTE('AQUA POINTS'!$1:$1,CHAR(160),"" ""))))), col, MATCH(UPPER(ev), hdrs, 0), base, INDEX('AQUA POINTS'!$1:$3, IF(gen=""M"",2,3), col), baseSec, IF(ISNUMBER(base), IF(ba"&"se<1, base*86400, base), IF(REGEXMATCH(base,"":""), VALUE(LEFT(base, FIND("":"",base)-1))*60 + VALUE(MID(base, FIND("":"",base)+1, 99)), VALUE(SUBSTITUTE(base,"","",""."")))), tSec, IF(ISNUMBER(t), IF(t<1, t*86400, t), "&" IF(REGEXMATCH(t,"":""), VALUE(LEFT(t, FIND("":"",t)-1))*60 + VALUE(MID(t, FIND("":"",t)+1, 99)), VALUE(SUBSTITUTE(t,"","",""."")))), INT(1000*(baseSec/tSec)^3) )"),721.0) -> 721
A24: F | B24: 100 Breast | C24: 15 | D24: 1 | E24: 1:09.68 | F24: =IFERROR(__xludf.DUMMYFUNCTION("IF( REGEXMATCH(E24, "":""), 60*VALUE(INDEX(SPLIT(E24, "":""),1,1)) + VALUE(INDEX(SPLIT(E24, "":""),1,2)), VALUE(E24) )"),69.68) -> 69.68 | G24: 0 | H24: 0 | I24: =C24 -> 15 | J24: =C41 -> 23 | K24: {=INDEX('Podium Target Times'!$C:$C, MATCH(A24&B24, 'Podium Target Times'!$A:$A&'Podium Target Times'!$B:$B, 0))} -> 70.94 | L24: =L25+G25 -> 75.43 | M24: =IF(L24<60, TEXT(L24,"0.00"), IF(L24<600, TEXT(L24/86400,"m:ss.00"), TEXT(L24/86400,"mm:ss.00"))) -> 1:15.43 | N24: =IFERROR(__xludf.DUMMYFUNCTION("LET( gen,$A24, ev,$B24, t,$M24, hdrs, ARRAYFORMULA(UPPER(TRIM(CLEAN(SUBSTITUTE('AQUA POINTS'!$1:$1,CHAR(160),"" ""))))), col, MATCH(UPPER(ev), hdrs, 0), base, INDEX('AQUA POINTS'!$1:$3, IF(gen=""M"",2,3), col), baseSec, IF(ISNUMBER(base), IF(ba"&"se<1, base*86400, base), IF(REGEXMATCH(base,"":""), VALUE(LEFT(base, FIND("":"",base)-1))*60 + VALUE(MID(base, FIND("":"",base)+1, 99)), VALUE(SUBSTITUTE(base,"","",""."")))), tSec, IF(ISNUMBER(t), IF(t<1, t*86400, t), "&" IF(REGEXMATCH(t,"":""), VALUE(LEFT(t, FIND("":"",t)-1))*60 + VALUE(MID(t, FIND("":"",t)+1, 99)), VALUE(SUBSTITUTE(t,"","",""."")))), INT(1000*(baseSec/tSec)^3) )"),614.0) -> 614
A25: F | B25: 100 Breast | C25: 16 | D25: 1 | E25: 1:08.45 | F25: =IFERROR(__xludf.DUMMYFUNCTION("IF( REGEXMATCH(E25, "":""), 60*VALUE(INDEX(SPLIT(E25, "":""),1,1)) + VALUE(INDEX(SPLIT(E25, "":""),1,2)), VALUE(E25) )"),68.45) -> 68.45 | G25: =F24-F25 -> 1.23 | H25: 1.23 | I25: =C24 -> 15 | J25: =C41 -> 23 | K25: {=INDEX('Podium Target Times'!$C:$C, MATCH(A25&B25, 'Podium Target Times'!$A:$A&'Podium Target Times'!$B:$B, 0))} -> 70.94 | L25: =L27+G27 -> 74.2 | M25: =IF(L25<60, TEXT(L25,"0.00"), IF(L25<600, TEXT(L25/86400,"m:ss.00"), TEXT(L25/86400,"mm:ss.00"))) -> 1:14.20 | N25: =IFERROR(__xludf.DUMMYFUNCTION("LET( gen,$A25, ev,$B25, t,$M25, hdrs, ARRAYFORMULA(UPPER(TRIM(CLEAN(SUBSTITUTE('AQUA POINTS'!$1:$1,CHAR(160),"" ""))))), col, MATCH(UPPER(ev), hdrs, 0), base, INDEX('AQUA POINTS'!$1:$3, IF(gen=""M"",2,3), col), baseSec, IF(ISNUMBER(base), IF(ba"&"se<1, base*86400, base), IF(REGEXMATCH(base,"":""), VALUE(LEFT(base, FIND("":"",base)-1))*60 + VALUE(MID(base, FIND("":"",base)+1, 99)), VALUE(SUBSTITUTE(base,"","",""."")))), tSec, IF(ISNUMBER(t), IF(t<1, t*86400, t), "&" IF(REGEXMATCH(t,"":""), VALUE(LEFT(t, FIND("":"",t)-1))*60 + VALUE(MID(t, FIND("":"",t)+1, 99)), VALUE(SUBSTITUTE(t,"","",""."")))), INT(1000*(baseSec/tSec)^3) )"),645.0) -> 645
A26: F | B26: 100 Breast | C26: 16 | D26: 2 | E26: 1:09.15 | F26: =IFERROR(__xludf.DUMMYFUNCTION("IF( REGEXMATCH(E26, "":""), 60*VALUE(INDEX(SPLIT(E26, "":""),1,1)) + VALUE(INDEX(SPLIT(E26, "":""),1,2)), VALUE(E26) )"),69.15) -> 69.15 | G26: =F24-F25 -> 1.23 | H26: 1.23 | I26: =C24 -> 15 | J26: =C41 -> 23 | K26: {=INDEX('Podium Target Times'!$C:$C, MATCH(A26&B26, 'Podium Target Times'!$A:$A&'Podium Target Times'!$B:$B, 0))} -> 70.94 | L26: =L27+G27 -> 74.2 | M26: =IF(L26<60, TEXT(L26,"0.00"), IF(L26<600, TEXT(L26/86400,"m:ss.00"), TEXT(L26/86400,"mm:ss.00"))) -> 1:14.20 | N26: =IFERROR(__xludf.DUMMYFUNCTION("LET( gen,$A26, ev,$B26, t,$M26, hdrs, ARRAYFORMULA(UPPER(TRIM(CLEAN(SUBSTITUTE('AQUA POINTS'!$1:$1,CHAR(160),"" ""))))), col, MATCH(UPPER(ev), hdrs, 0), base, INDEX('AQUA POINTS'!$1:$3, IF(gen=""M"",2,3), col), baseSec, IF(ISNUMBER(base), IF(ba"&"se<1, base*86400, base), IF(REGEXMATCH(base,"":""), VALUE(LEFT(base, FIND("":"",base)-1))*60 + VALUE(MID(base, FIND("":"",base)+1, 99)), VALUE(SUBSTITUTE(base,"","",""."")))), tSec, IF(ISNUMBER(t), IF(t<1, t*86400, t), "&" IF(REGEXMATCH(t,"":""), VALUE(LEFT(t, FIND("":"",t)-1))*60 + VALUE(MID(t, FIND("":"",t)+1, 99)), VALUE(SUBSTITUTE(t,"","",""."")))), INT(1000*(baseSec/tSec)^3) )"),645.0) -> 645
A27: F | B27: 100 Breast | C27: 17 | D27: 1 | E27: 1:07.71 | F27: =IFERROR(__xludf.DUMMYFUNCTION("IF( REGEXMATCH(E27, "":""), 60*VALUE(INDEX(SPLIT(E27, "":""),1,1)) + VALUE(INDEX(SPLIT(E27, "":""),1,2)), VALUE(E27) )"),67.71) -> 67.71 | G27: =average(F25-F27,F26-F28) -> 0.745 | H27: 0.745 | I27: =C24 -> 15 | J27: =C41 -> 23 | K27: {=INDEX('Podium Target Times'!$C:$C, MATCH(A27&B27, 'Podium Target Times'!$A:$A&'Podium Target Times'!$B:$B, 0))} -> 70.94 | L27: =L30+G30 -> 73.455 | M27: =IF(L27<60, TEXT(L27,"0.00"), IF(L27<600, TEXT(L27/86400,"m:ss.00"), TEXT(L27/86400,"mm:ss.00"))) -> 1:13.46 | N27: =IFERROR(__xludf.DUMMYFUNCTION("LET( gen,$A27, ev,$B27, t,$M27, hdrs, ARRAYFORMULA(UPPER(TRIM(CLEAN(SUBSTITUTE('AQUA POINTS'!$1:$1,CHAR(160),"" ""))))), col, MATCH(UPPER(ev), hdrs, 0), base, INDEX('AQUA POINTS'!$1:$3, IF(gen=""M"",2,3), col), baseSec, IF(ISNUMBER(base), IF(ba"&"se<1, base*86400, base), IF(REGEXMATCH(base,"":""), VALUE(LEFT(base, FIND("":"",base)-1))*60 + VALUE(MID(base, FIND("":"",base)+1, 99)), VALUE(SUBSTITUTE(base,"","",""."")))), tSec, IF(ISNUMBER(t), IF(t<1, t*86400, t), "&" IF(REGEXMATCH(t,"":""), VALUE(LEFT(t, FIND("":"",t)-1))*60 + VALUE(MID(t, FIND("":"",t)+1, 99)), VALUE(SUBSTITUTE(t,"","",""."")))), INT(1000*(baseSec/tSec)^3) )"),665.0) -> 665
A28: F | B28: 100 Breast | C28: 17 | D28: 2 | E28: 1:08.40 | F28: =IFERROR(__xludf.DUMMYFUNCTION("IF( REGEXMATCH(E28, "":""), 60*VALUE(INDEX(SPLIT(E28, "":""),1,1)) + VALUE(INDEX(SPLIT(E28, "":""),1,2)), VALUE(E28) )"),68.4) -> 68.4 | G28: =average(F25-F27,F26-F28) -> 0.745 | H28: 0.745 | I28: =C24 -> 15 | J28: =C41 -> 23 | K28: {=INDEX('Podium Target Times'!$C:$C, MATCH(A28&B28, 'Podium Target Times'!$A:$A&'Podium Target Times'!$B:$B, 0))} -> 70.94 | L28: =L30+G30 -> 73.455 | M28: =IF(L28<60, TEXT(L28,"0.00"), IF(L28<600, TEXT(L28/86400,"m:ss.00"), TEXT(L28/86400,"mm:ss.00"))) -> 1:13.46 | N28: =IFERROR(__xludf.DUMMYFUNCTION("LET( gen,$A28, ev,$B28, t,$M28, hdrs, ARRAYFORMULA(UPPER(TRIM(CLEAN(SUBSTITUTE('AQUA POINTS'!$1:$1,CHAR(160),"" ""))))), col, MATCH(UPPER(ev), hdrs, 0), base, INDEX('AQUA POINTS'!$1:$3, IF(gen=""M"",2,3), col), baseSec, IF(ISNUMBER(base), IF(ba"&"se<1, base*86400, base), IF(REGEXMATCH(base,"":""), VALUE(LEFT(base, FIND("":"",base)-1))*60 + VALUE(MID(base, FIND("":"",base)+1, 99)), VALUE(SUBSTITUTE(base,"","",""."")))), tSec, IF(ISNUMBER(t), IF(t<1, t*86400, t), "&" IF(REGEXMATCH(t,"":""), VALUE(LEFT(t, FIND("":"",t)-1))*60 + VALUE(MID(t, FIND("":"",t)+1, 99)), VALUE(SUBSTITUTE(t,"","",""."")))), INT(1000*(baseSec/tSec)^3) )"),665.0) -> 665
A29: F | B29: 100 Breast | C29: 17 | D29: 3 | E29: 1:08.94 | F29: =IFERROR(__xludf.DUMMYFUNCTION("IF( REGEXMATCH(E29, "":""), 60*VALUE(INDEX(SPLIT(E29, "":""),1,1)) + VALUE(INDEX(SPLIT(E29, "":""),1,2)), VALUE(E29) )"),68.94) -> 68.94 | G29: =average(F25-F27,F26-F28) -> 0.745 | H29: 0.745 | I29: =C24 -> 15 | J29: =C41 -> 23 | K29: {=INDEX('Podium Target Times'!$C:$C, MATCH(A29&B29, 'Podium Target Times'!$A:$A&'Podium Target Times'!$B:$B, 0))} -> 70.94 | L29: =L30+G30 -> 73.455 | M29: =IF(L29<60, TEXT(L29,"0.00"), IF(L29<600, TEXT(L29/86400,"m:ss.00"), TEXT(L29/86400,"mm:ss.00"))) -> 1:13.46 | N29: =IFERROR(__xludf.DUMMYFUNCTION("LET( gen,$A29, ev,$B29, t,$M29, hdrs, ARRAYFORMULA(UPPER(TRIM(CLEAN(SUBSTITUTE('AQUA POINTS'!$1:$1,CHAR(160),"" ""))))), col, MATCH(UPPER(ev), hdrs, 0), base, INDEX('AQUA POINTS'!$1:$3, IF(gen=""M"",2,3), col), baseSec, IF(ISNUMBER(base), IF(ba"&"se<1, base*86400, base), IF(REGEXMATCH(base,"":""), VALUE(LEFT(base, FIND("":"",base)-1))*60 + VALUE(MID(base, FIND("":"",base)+1, 99)), VALUE(SUBSTITUTE(base,"","",""."")))), tSec, IF(ISNUMBER(t), IF(t<1, t*86400, t), "&" IF(REGEXMATCH(t,"":""), VALUE(LEFT(t, FIND("":"",t)-1))*60 + VALUE(MID(t, FIND("":"",t)+1, 99)), VALUE(SUBSTITUTE(t,"","",""."")))), INT(1000*(baseSec/tSec)^3) )"),665.0) -> 665
A30: F | B30: 100 Breast | C30: 18 | D30: 1 | E30: 1:07.24 | F30: =IFERROR(__xludf.DUMMYFUNCTION("IF( REGEXMATCH(E30, "":""), 60*VALUE(INDEX(SPLIT(E30, "":""),1,1)) + VALUE(INDEX(SPLIT(E30, "":""),1,2)), VALUE(E30) )"),67.24) -> 67.24 | G30: =average(F27-F30,F28-F31,F29-F32) -> 0.47666667 | H30: 0.47666667 | I30: =C24 -> 15 | J30: =C41 -> 23 | K30: {=INDEX('Podium Target Times'!$C:$C, MATCH(A30&B30, 'Podium Target Times'!$A:$A&'Podium Target Times'!$B:$B, 0))} -> 70.94 | L30: =L33+G33 -> 72.978333 | M30: =IF(L30<60, TEXT(L30,"0.00"), IF(L30<600, TEXT(L30/86400,"m:ss.00"), TEXT(L30/86400,"mm:ss.00"))) -> 1:12.98 | N30: =IFERROR(__xludf.DUMMYFUNCTION("LET( gen,$A30, ev,$B30, t,$M30, hdrs, ARRAYFORMULA(UPPER(TRIM(CLEAN(SUBSTITUTE('AQUA POINTS'!$1:$1,CHAR(160),"" ""))))), col, MATCH(UPPER(ev), hdrs, 0), base, INDEX('AQUA POINTS'!$1:$3, IF(gen=""M"",2,3), col), baseSec, IF(ISNUMBER(base), IF(ba"&"se<1, base*86400, base), IF(REGEXMATCH(base,"":""), VALUE(LEFT(base, FIND("":"",base)-1))*60 + VALUE(MID(base, FIND("":"",base)+1, 99)), VALUE(SUBSTITUTE(base,"","",""."")))), tSec, IF(ISNUMBER(t), IF(t<1, t*86400, t), "&" IF(REGEXMATCH(t,"":""), VALUE(LEFT(t, FIND("":"",t)-1))*60 + VALUE(MID(t, FIND("":"",t)+1, 99)), VALUE(SUBSTITUTE(t,"","",""."")))), INT(1000*(baseSec/tSec)^3) )"),678.0) -> 678
A31: F | B31: 100 Breast | C31: 18 | D31: 2 | E31: 1:07.92 | F31: =IFERROR(__xludf.DUMMYFUNCTION("IF( REGEXMATCH(E31, "":""), 60*VALUE(INDEX(SPLIT(E31, "":""),1,1)) + VALUE(INDEX(SPLIT(E31, "":""),1,2)), VALUE(E31) )"),67.92) -> 67.92 | G31: =average(F27-F30,F28-F31,F29-F32) -> 0.47666667 | H31: 0.47666667 | I31: =C24 -> 15 | J31: =C41 -> 23 | K31: {=INDEX('Podium Target Times'!$C:$C, MATCH(A31&B31, 'Podium Target Times'!$A:$A&'Podium Target Times'!$B:$B, 0))} -> 70.94 | L31: =L33+G33 -> 72.978333 | M31: =IF(L31<60, TEXT(L31,"0.00"), IF(L31<600, TEXT(L31/86400,"m:ss.00"), TEXT(L31/86400,"mm:ss.00"))) -> 1:12.98 | N31: =IFERROR(__xludf.DUMMYFUNCTION("LET( gen,$A31, ev,$B31, t,$M31, hdrs, ARRAYFORMULA(UPPER(TRIM(CLEAN(SUBSTITUTE('AQUA POINTS'!$1:$1,CHAR(160),"" ""))))), col, MATCH(UPPER(ev), hdrs, 0), base, INDEX('AQUA POINTS'!$1:$3, IF(gen=""M"",2,3), col), baseSec, IF(ISNUMBER(base), IF(ba"&"se<1, base*86400, base), IF(REGEXMATCH(base,"":""), VALUE(LEFT(base, FIND("":"",base)-1))*60 + VALUE(MID(base, FIND("":"",base)+1, 99)), VALUE(SUBSTITUTE(base,"","",""."")))), tSec, IF(ISNUMBER(t), IF(t<1, t*86400, t), "&" IF(REGEXMATCH(t,"":""), VALUE(LEFT(t, FIND("":"",t)-1))*60 + VALUE(MID(t, FIND("":"",t)+1, 99)), VALUE(SUBSTITUTE(t,"","",""."")))), INT(1000*(baseSec/tSec)^3) )"),678.0) -> 678
A32: F | B32: 100 Breast | C32: 18 | D32: 3 | E32: 1:08.46 | F32: =IFERROR(__xludf.DUMMYFUNCTION("IF( REGEXMATCH(E32, "":""), 60*VALUE(INDEX(SPLIT(E32, "":""),1,1)) + VALUE(INDEX(SPLIT(E32, "":""),1,2)), VALUE(E32) )"),68.46000000000001) -> 68.46 | G32: =average(F27-F30,F28-F31,F29-F32) -> 0.47666667 | H32: 0.47666667 | I32: =C24 -> 15 | J32: =C41 -> 23 | K32: {=INDEX('Podium Target Times'!$C:$C, MATCH(A32&B32, 'Podium Target Times'!$A:$A&'Podium Target Times'!$B:$B, 0))} -> 70.94 | L32: =L33+G33 -> 72.978333 | M32: =IF(L32<60, TEXT(L32,"0.00"), IF(L32<600, TEXT(L32/86400,"m:ss.00"), TEXT(L32/86400,"mm:ss.00"))) -> 1:12.98 | N32: =IFERROR(__xludf.DUMMYFUNCTION("LET( gen,$A32, ev,$B32, t,$M32, hdrs, ARRAYFORMULA(UPPER(TRIM(CLEAN(SUBSTITUTE('AQUA POINTS'!$1:$1,CHAR(160),"" ""))))), col, MATCH(UPPER(ev), hdrs, 0), base, INDEX('AQUA POINTS'!$1:$3, IF(gen=""M"",2,3), col), baseSec, IF(ISNUMBER(base), IF(ba"&"se<1, base*86400, base), IF(REGEXMATCH(base,"":""), VALUE(LEFT(base, FIND("":"",base)-1))*60 + VALUE(MID(base, FIND("":"",base)+1, 99)), VALUE(SUBSTITUTE(base,"","",""."")))), tSec, IF(ISNUMBER(t), IF(t<1, t*86400, t), "&" IF(REGEXMATCH(t,"":""), VALUE(LEFT(t, FIND("":"",t)-1))*60 + VALUE(MID(t, FIND("":"",t)+1, 99)), VALUE(SUBSTITUTE(t,"","",""."")))), INT(1000*(baseSec/tSec)^3) )"),678.0) -> 678
A33: F | B33: 100 Breast | C33: 19 | D33: 1 | E33: 1:06.87 | F33: =IFERROR(__xludf.DUMMYFUNCTION("IF( REGEXMATCH(E33, "":""), 60*VALUE(INDEX(SPLIT(E33, "":""),1,1)) + VALUE(INDEX(SPLIT(E33, "":""),1,2)), VALUE(E33) )"),66.87) -> 66.87 | G33: =average(F30-F33,F31-F34,F32-F35) -> 0.37333333 | H33: 0.37333333 | I33: =C24 -> 15 | J33: =C41 -> 23 | K33: {=INDEX('Podium Target Times'!$C:$C, MATCH(A33&B33, 'Podium Target Times'!$A:$A&'Podium Target Times'!$B:$B, 0))} -> 70.94 | L33: =L36+G36 -> 72.605 | M33: =IF(L33<60, TEXT(L33,"0.00"), IF(L33<600, TEXT(L33/86400,"m:ss.00"), TEXT(L33/86400,"mm:ss.00"))) -> 1:12.61 | N33: =IFERROR(__xludf.DUMMYFUNCTION("LET( gen,$A33, ev,$B33, t,$M33, hdrs, ARRAYFORMULA(UPPER(TRIM(CLEAN(SUBSTITUTE('AQUA POINTS'!$1:$1,CHAR(160),"" ""))))), col, MATCH(UPPER(ev), hdrs, 0), base, INDEX('AQUA POINTS'!$1:$3, IF(gen=""M"",2,3), col), baseSec, IF(ISNUMBER(base), IF(ba"&"se<1, base*86400, base), IF(REGEXMATCH(base,"":""), VALUE(LEFT(base, FIND("":"",base)-1))*60 + VALUE(MID(base, FIND("":"",base)+1, 99)), VALUE(SUBSTITUTE(base,"","",""."")))), tSec, IF(ISNUMBER(t), IF(t<1, t*86400, t), "&" IF(REGEXMATCH(t,"":""), VALUE(LEFT(t, FIND("":"",t)-1))*60 + VALUE(MID(t, FIND("":"",t)+1, 99)), VALUE(SUBSTITUTE(t,"","",""."")))), INT(1000*(baseSec/tSec)^3) )"),688.0) -> 688
A34: F | B34: 100 Breast | C34: 19 | D34: 2 | E34: 1:07.55 | F34: =IFERROR(__xludf.DUMMYFUNCTION("IF( REGEXMATCH(E34, "":""), 60*VALUE(INDEX(SPLIT(E34, "":""),1,1)) + VALUE(INDEX(SPLIT(E34, "":""),1,2)), VALUE(E34) )"),67.55) -> 67.55 | G34: =average(F30-F33,F31-F34,F32-F35) -> 0.37333333 | H34: 0.37333333 | I34: =C24 -> 15 | J34: =C41 -> 23 | K34: {=INDEX('Podium Target Times'!$C:$C, MATCH(A34&B34, 'Podium Target Times'!$A:$A&'Podium Target Times'!$B:$B, 0))} -> 70.94 | L34: =L36+G36 -> 72.605 | M34: =IF(L34<60, TEXT(L34,"0.00"), IF(L34<600, TEXT(L34/86400,"m:ss.00"), TEXT(L34/86400,"mm:ss.00"))) -> 1:12.61 | N34: =IFERROR(__xludf.DUMMYFUNCTION("LET( gen,$A34, ev,$B34, t,$M34, hdrs, ARRAYFORMULA(UPPER(TRIM(CLEAN(SUBSTITUTE('AQUA POINTS'!$1:$1,CHAR(160),"" ""))))), col, MATCH(UPPER(ev), hdrs, 0), base, INDEX('AQUA POINTS'!$1:$3, IF(gen=""M"",2,3), col), baseSec, IF(ISNUMBER(base), IF(ba"&"se<1, base*86400, base), IF(REGEXMATCH(base,"":""), VALUE(LEFT(base, FIND("":"",base)-1))*60 + VALUE(MID(base, FIND("":"",base)+1, 99)), VALUE(SUBSTITUTE(base,"","",""."")))), tSec, IF(ISNUMBER(t), IF(t<1, t*86400, t), "&" IF(REGEXMATCH(t,"":""), VALUE(LEFT(t, FIND("":"",t)-1))*60 + VALUE(MID(t, FIND("":"",t)+1, 99)), VALUE(SUBSTITUTE(t,"","",""."")))), INT(1000*(baseSec/tSec)^3) )"),688.0) -> 688
A35: F | B35: 100 Breast | C35: 19 | D35: 3 | E35: 1:08.08 | F35: =IFERROR(__xludf.DUMMYFUNCTION("IF( REGEXMATCH(E35, "":""), 60*VALUE(INDEX(SPLIT(E35, "":""),1,1)) + VALUE(INDEX(SPLIT(E35, "":""),1,2)), VALUE(E35) )"),68.08) -> 68.08 | G35: =average(F30-F33,F31-F34,F32-F35) -> 0.37333333 | H35: 0.37333333 | I35: =C24 -> 15 | J35: =C41 -> 23 | K35: {=INDEX('Podium Target Times'!$C:$C, MATCH(A35&B35, 'Podium Target Times'!$A:$A&'Podium Target Times'!$B:$B, 0))} -> 70.94 | L35: =L36+G36 -> 72.605 | M35: =IF(L35<60, TEXT(L35,"0.00"), IF(L35<600, TEXT(L35/86400,"m:ss.00"), TEXT(L35/86400,"mm:ss.00"))) -> 1:12.61 | N35: =IFERROR(__xludf.DUMMYFUNCTION("LET( gen,$A35, ev,$B35, t,$M35, hdrs, ARRAYFORMULA(UPPER(TRIM(CLEAN(SUBSTITUTE('AQUA POINTS'!$1:$1,CHAR(160),"" ""))))), col, MATCH(UPPER(ev), hdrs, 0), base, INDEX('AQUA POINTS'!$1:$3, IF(gen=""M"",2,3), col), baseSec, IF(ISNUMBER(base), IF(ba"&"se<1, base*86400, base), IF(REGEXMATCH(base,"":""), VALUE(LEFT(base, FIND("":"",base)-1))*60 + VALUE(MID(base, FIND("":"",base)+1, 99)), VALUE(SUBSTITUTE(base,"","",""."")))), tSec, IF(ISNUMBER(t), IF(t<1, t*86400, t), "&" IF(REGEXMATCH(t,"":""), VALUE(LEFT(t, FIND("":"",t)-1))*60 + VALUE(MID(t, FIND("":"",t)+1, 99)), VALUE(SUBSTITUTE(t,"","",""."")))), INT(1000*(baseSec/tSec)^3) )"),688.0) -> 688
A36: F | B36: 100 Breast | C36: 20 | D36: 2 | E36: 1:07.20 | F36: =IFERROR(__xludf.DUMMYFUNCTION("IF( REGEXMATCH(E36, "":""), 60*VALUE(INDEX(SPLIT(E36, "":""),1,1)) + VALUE(INDEX(SPLIT(E36, "":""),1,2)), VALUE(E36) )"),67.2) -> 67.2 | G36: =average(F34-F36,F35-F37) -> 0.35 | H36: 0.35 | I36: =C24 -> 15 | J36: =C41 -> 23 | K36: {=INDEX('Podium Target Times'!$C:$C, MATCH(A36&B36, 'Podium Target Times'!$A:$A&'Podium Target Times'!$B:$B, 0))} -> 70.94 | L36: =L38+G38 -> 72.255 | M36: =IF(L36<60, TEXT(L36,"0.00"), IF(L36<600, TEXT(L36/86400,"m:ss.00"), TEXT(L36/86400,"mm:ss.00"))) -> 1:12.26 | N36: =IFERROR(__xludf.DUMMYFUNCTION("LET( gen,$A36, ev,$B36, t,$M36, hdrs, ARRAYFORMULA(UPPER(TRIM(CLEAN(SUBSTITUTE('AQUA POINTS'!$1:$1,CHAR(160),"" ""))))), col, MATCH(UPPER(ev), hdrs, 0), base, INDEX('AQUA POINTS'!$1:$3, IF(gen=""M"",2,3), col), baseSec, IF(ISNUMBER(base), IF(ba"&"se<1, base*86400, base), IF(REGEXMATCH(base,"":""), VALUE(LEFT(base, FIND("":"",base)-1))*60 + VALUE(MID(base, FIND("":"",base)+1, 99)), VALUE(SUBSTITUTE(base,"","",""."")))), tSec, IF(ISNUMBER(t), IF(t<1, t*86400, t), "&" IF(REGEXMATCH(t,"":""), VALUE(LEFT(t, FIND("":"",t)-1))*60 + VALUE(MID(t, FIND("":"",t)+1, 99)), VALUE(SUBSTITUTE(t,"","",""."")))), INT(1000*(baseSec/tSec)^3) )"),699.0) -> 699
A37: F | B37: 100 Breast | C37: 20 | D37: 3 | E37: 1:07.73 | F37: =IFERROR(__xludf.DUMMYFUNCTION("IF( REGEXMATCH(E37, "":""), 60*VALUE(INDEX(SPLIT(E37, "":""),1,1)) + VALUE(INDEX(SPLIT(E37, "":""),1,2)), VALUE(E37) )"),67.73) -> 67.73 | G37: =average(F34-F36,F35-F37) -> 0.35 | H37: 0.35 | I37: =C24 -> 15 | J37: =C41 -> 23 | K37: {=INDEX('Podium Target Times'!$C:$C, MATCH(A37&B37, 'Podium Target Times'!$A:$A&'Podium Target Times'!$B:$B, 0))} -> 70.94 | L37: =L38+G38 -> 72.255 | M37: =IF(L37<60, TEXT(L37,"0.00"), IF(L37<600, TEXT(L37/86400,"m:ss.00"), TEXT(L37/86400,"mm:ss.00"))) -> 1:12.26 | N37: =IFERROR(__xludf.DUMMYFUNCTION("LET( gen,$A37, ev,$B37, t,$M37, hdrs, ARRAYFORMULA(UPPER(TRIM(CLEAN(SUBSTITUTE('AQUA POINTS'!$1:$1,CHAR(160),"" ""))))), col, MATCH(UPPER(ev), hdrs, 0), base, INDEX('AQUA POINTS'!$1:$3, IF(gen=""M"",2,3), col), baseSec, IF(ISNUMBER(base), IF(ba"&"se<1, base*86400, base), IF(REGEXMATCH(base,"":""), VALUE(LEFT(base, FIND("":"",base)-1))*60 + VALUE(MID(base, FIND("":"",base)+1, 99)), VALUE(SUBSTITUTE(base,"","",""."")))), tSec, IF(ISNUMBER(t), IF(t<1, t*86400, t), "&" IF(REGEXMATCH(t,"":""), VALUE(LEFT(t, FIND("":"",t)-1))*60 + VALUE(MID(t, FIND("":"",t)+1, 99)), VALUE(SUBSTITUTE(t,"","",""."")))), INT(1000*(baseSec/tSec)^3) )"),699.0) -> 699
A38: F | B38: 100 Breast | C38: 21 | D38: 2 | E38: 1:06.87 | F38: =IFERROR(__xludf.DUMMYFUNCTION("IF( REGEXMATCH(E38, "":""), 60*VALUE(INDEX(SPLIT(E38, "":""),1,1)) + VALUE(INDEX(SPLIT(E38, "":""),1,2)), VALUE(E38) )"),66.87) -> 66.87 | G38: =average(F36-F38,F37-F39) -> 0.335 | H38: 0.335 | I38: =C24 -> 15 | J38: =C41 -> 23 | K38: {=INDEX('Podium Target Times'!$C:$C, MATCH(A38&B38, 'Podium Target Times'!$A:$A&'Podium Target Times'!$B:$B, 0))} -> 70.94 | L38: =L40+G40 -> 71.92 | M38: =IF(L38<60, TEXT(L38,"0.00"), IF(L38<600, TEXT(L38/86400,"m:ss.00"), TEXT(L38/86400,"mm:ss.00"))) -> 1:11.92 | N38: =IFERROR(__xludf.DUMMYFUNCTION("LET( gen,$A38, ev,$B38, t,$M38, hdrs, ARRAYFORMULA(UPPER(TRIM(CLEAN(SUBSTITUTE('AQUA POINTS'!$1:$1,CHAR(160),"" ""))))), col, MATCH(UPPER(ev), hdrs, 0), base, INDEX('AQUA POINTS'!$1:$3, IF(gen=""M"",2,3), col), baseSec, IF(ISNUMBER(base), IF(ba"&"se<1, base*86400, base), IF(REGEXMATCH(base,"":""), VALUE(LEFT(base, FIND("":"",base)-1))*60 + VALUE(MID(base, FIND("":"",base)+1, 99)), VALUE(SUBSTITUTE(base,"","",""."")))), tSec, IF(ISNUMBER(t), IF(t<1, t*86400, t), "&" IF(REGEXMATCH(t,"":""), VALUE(LEFT(t, FIND("":"",t)-1))*60 + VALUE(MID(t, FIND("":"",t)+1, 99)), VALUE(SUBSTITUTE(t,"","",""."")))), INT(1000*(baseSec/tSec)^3) )"),708.0) -> 708
A39: F | B39: 100 Breast | C39: 21 | D39: 3 | E39: 1:07.39 | F39: =IFERROR(__xludf.DUMMYFUNCTION("IF( REGEXMATCH(E39, "":""), 60*VALUE(INDEX(SPLIT(E39, "":""),1,1)) + VALUE(INDEX(SPLIT(E39, "":""),1,2)), VALUE(E39) )"),67.39) -> 67.39 | G39: =average(F36-F38,F37-F39) -> 0.335 | H39: 0.335 | I39: =C24 -> 15 | J39: =C41 -> 23 | K39: {=INDEX('Podium Target Times'!$C:$C, MATCH(A39&B39, 'Podium Target Times'!$A:$A&'Podium Target Times'!$B:$B, 0))} -> 70.94 | L39: =L40+G40 -> 71.92 | M39: =IF(L39<60, TEXT(L39,"0.00"), IF(L39<600, TEXT(L39/86400,"m:ss.00"), TEXT(L39/86400,"mm:ss.00"))) -> 1:11.92 | N39: =IFERROR(__xludf.DUMMYFUNCTION("LET( gen,$A39, ev,$B39, t,$M39, hdrs, ARRAYFORMULA(UPPER(TRIM(CLEAN(SUBSTITUTE('AQUA POINTS'!$1:$1,CHAR(160),"" ""))))), col, MATCH(UPPER(ev), hdrs, 0), base, INDEX('AQUA POINTS'!$1:$3, IF(gen=""M"",2,3), col), baseSec, IF(ISNUMBER(base), IF(ba"&"se<1, base*86400, base), IF(REGEXMATCH(base,"":""), VALUE(LEFT(base, FIND("":"",base)-1))*60 + VALUE(MID(base, FIND("":"",base)+1, 99)), VALUE(SUBSTITUTE(base,"","",""."")))), tSec, IF(ISNUMBER(t), IF(t<1, t*86400, t), "&" IF(REGEXMATCH(t,"":""), VALUE(LEFT(t, FIND("":"",t)-1))*60 + VALUE(MID(t, FIND("":"",t)+1, 99)), VALUE(SUBSTITUTE(t,"","",""."")))), INT(1000*(baseSec/tSec)^3) )"),708.0) -> 708
A40: F | B40: 100 Breast | C40: 22 | D40: 3 | E40: 1:07.10 | F40: =IFERROR(__xludf.DUMMYFUNCTION("IF( REGEXMATCH(E40, "":""), 60*VALUE(INDEX(SPLIT(E40, "":""),1,1)) + VALUE(INDEX(SPLIT(E40, "":""),1,2)), VALUE(E40) )"),67.1) -> 67.1 | G40: =F39-F40 -> 0.29 | H40: 0.29 | I40: =C24 -> 15 | J40: =C41 -> 23 | K40: {=INDEX('Podium Target Times'!$C:$C, MATCH(A40&B40, 'Podium Target Times'!$A:$A&'Podium Target Times'!$B:$B, 0))} -> 70.94 | L40: =L41+G41 -> 71.63 | M40: =IF(L40<60, TEXT(L40,"0.00"), IF(L40<600, TEXT(L40/86400,"m:ss.00"), TEXT(L40/86400,"mm:ss.00"))) -> 1:11.63 | N40: =IFERROR(__xludf.DUMMYFUNCTION("LET( gen,$A40, ev,$B40, t,$M40, hdrs, ARRAYFORMULA(UPPER(TRIM(CLEAN(SUBSTITUTE('AQUA POINTS'!$1:$1,CHAR(160),"" ""))))), col, MATCH(UPPER(ev), hdrs, 0), base, INDEX('AQUA POINTS'!$1:$3, IF(gen=""M"",2,3), col), baseSec, IF(ISNUMBER(base), IF(ba"&"se<1, base*86400, base), IF(REGEXMATCH(base,"":""), VALUE(LEFT(base, FIND("":"",base)-1))*60 + VALUE(MID(base, FIND("":"",base)+1, 99)), VALUE(SUBSTITUTE(base,"","",""."")))), tSec, IF(ISNUMBER(t), IF(t<1, t*86400, t), "&" IF(REGEXMATCH(t,"":""), VALUE(LEFT(t, FIND("":"",t)-1))*60 + VALUE(MID(t, FIND("":"",t)+1, 99)), VALUE(SUBSTITUTE(t,"","",""."")))), INT(1000*(baseSec/tSec)^3) )"),717.0) -> 717
...

Sheet Podium Target Times
A1: Gender | B1: Event | C1: Time | D1: AQUA
A2: M | B2: 50 Free | C2: 22.84 | D2: =IFERROR(__xludf.DUMMYFUNCTION("LET( gen,$A2, ev,$B2, t,$C2, hdrs, ARRAYFORMULA(UPPER(TRIM(CLEAN(SUBSTITUTE('AQUA POINTS'!$1:$1,CHAR(160),"" ""))))), col, MATCH(UPPER(ev), hdrs, 0), base, INDEX('AQUA POINTS'!$1:$3, IF(gen=""M"",2,3), col), baseSec, IF(ISNUMBER(base), IF(base<"&"1, base*86400, base), IF(REGEXMATCH(base,"":""), VALUE(LEFT(base, FIND("":"",base)-1))*60 + VALUE(MID(base, FIND("":"",base)+1, 99)), VALUE(SUBSTITUTE(base,"","",""."")))), tSec, IF(ISNUMBER(t), IF(t<1, t*86400, t), "&" IF(REGEXMATCH(t,"":""), VALUE(LEFT(t, FIND("":"",t)-1))*60 + VALUE(MID(t, FIND("":"",t)+1, 99)), VALUE(SUBSTITUTE(t,"","",""."")))), INT(1000*(baseSec/tSec)^3) )"),767.0) -> 767
A3: M | B3: 100 Free | C3: 49.69 | D3: =IFERROR(__xludf.DUMMYFUNCTION("LET( gen,$A3, ev,$B3, t,$C3, hdrs, ARRAYFORMULA(UPPER(TRIM(CLEAN(SUBSTITUTE('AQUA POINTS'!$1:$1,CHAR(160),"" ""))))), col, MATCH(UPPER(ev), hdrs, 0), base, INDEX('AQUA POINTS'!$1:$3, IF(gen=""M"",2,3), col), baseSec, IF(ISNUMBER(base), IF(base<"&"1, base*86400, base), IF(REGEXMATCH(base,"":""), VALUE(LEFT(base, FIND("":"",base)-1))*60 + VALUE(MID(base, FIND("":"",base)+1, 99)), VALUE(SUBSTITUTE(base,"","",""."")))), tSec, IF(ISNUMBER(t), IF(t<1, t*86400, t), "&" IF(REGEXMATCH(t,"":""), VALUE(LEFT(t, FIND("":"",t)-1))*60 + VALUE(MID(t, FIND("":"",t)+1, 99)), VALUE(SUBSTITUTE(t,"","",""."")))), INT(1000*(baseSec/tSec)^3) )"),814.0) -> 814
A4: M | B4: 200 Free | C4: 109.31 | D4: =IFERROR(__xludf.DUMMYFUNCTION("LET( gen,$A4, ev,$B4, t,$C4, hdrs, ARRAYFORMULA(UPPER(TRIM(CLEAN(SUBSTITUTE('AQUA POINTS'!$1:$1,CHAR(160),"" ""))))), col, MATCH(UPPER(ev), hdrs, 0), base, INDEX('AQUA POINTS'!$1:$3, IF(gen=""M"",2,3), col), baseSec, IF(ISNUMBER(base), IF(base<"&"1, base*86400, base), IF(REGEXMATCH(base,"":""), VALUE(LEFT(base, FIND("":"",base)-1))*60 + VALUE(MID(base, FIND("":"",base)+1, 99)), VALUE(SUBSTITUTE(base,"","",""."")))), tSec, IF(ISNUMBER(t), IF(t<1, t*86400, t), "&" IF(REGEXMATCH(t,"":""), VALUE(LEFT(t, FIND("":"",t)-1))*60 + VALUE(MID(t, FIND("":"",t)+1, 99)), VALUE(SUBSTITUTE(t,"","",""."")))), INT(1000*(baseSec/tSec)^3) )"),812.0) -> 812
A5: M | B5: 400 Free | C5: 233.78 | D5: =IFERROR(__xludf.DUMMYFUNCTION("LET( gen,$A5, ev,$B5, t,$C5, hdrs, ARRAYFORMULA(UPPER(TRIM(CLEAN(SUBSTITUTE('AQUA POINTS'!$1:$1,CHAR(160),"" ""))))), col, MATCH(UPPER(ev), hdrs, 0), base, INDEX('AQUA POINTS'!$1:$3, IF(gen=""M"",2,3), col), baseSec, IF(ISNUMBER(base), IF(base<"&"1, base*86400, base), IF(REGEXMATCH(base,"":""), VALUE(LEFT(base, FIND("":"",base)-1))*60 + VALUE(MID(base, FIND("":"",base)+1, 99)), VALUE(SUBSTITUTE(base,"","",""."")))), tSec, IF(ISNUMBER(t), IF(t<1, t*86400, t), "&" IF(REGEXMATCH(t,"":""), VALUE(LEFT(t, FIND("":"",t)-1))*60 + VALUE(MID(t, FIND("":"",t)+1, 99)), VALUE(SUBSTITUTE(t,"","",""."")))), INT(1000*(baseSec/tSec)^3) )"),834.0) -> 834
A6: M | B6: 800 Free | C6: 486.71 | D6: =IFERROR(__xludf.DUMMYFUNCTION("LET( gen,$A6, ev,$B6, t,$C6, hdrs, ARRAYFORMULA(UPPER(TRIM(CLEAN(SUBSTITUTE('AQUA POINTS'!$1:$1,CHAR(160),"" ""))))), col, MATCH(UPPER(ev), hdrs, 0), base, INDEX('AQUA POINTS'!$1:$3, IF(gen=""M"",2,3), col), baseSec, IF(ISNUMBER(base), IF(base<"&"1, base*86400, base), IF(REGEXMATCH(base,"":""), VALUE(LEFT(base, FIND("":"",base)-1))*60 + VALUE(MID(base, FIND("":"",base)+1, 99)), VALUE(SUBSTITUTE(base,"","",""."")))), tSec, IF(ISNUMBER(t), IF(t<1, t*86400, t), "&" IF(REGEXMATCH(t,"":""), VALUE(LEFT(t, FIND("":"",t)-1))*60 + VALUE(MID(t, FIND("":"",t)+1, 99)), VALUE(SUBSTITUTE(t,"","",""."")))), INT(1000*(baseSec/tSec)^3) )"),801.0) -> 801
A7: M | B7: 1500 Free | C7: 940.49 | D7: =IFERROR(__xludf.DUMMYFUNCTION("LET( gen,$A7, ev,$B7, t,$C7, hdrs, ARRAYFORMULA(UPPER(TRIM(CLEAN(SUBSTITUTE('AQUA POINTS'!$1:$1,CHAR(160),"" ""))))), col, MATCH(UPPER(ev), hdrs, 0), base, INDEX('AQUA POINTS'!$1:$3, IF(gen=""M"",2,3), col), baseSec, IF(ISNUMBER(base), IF(base<"&"1, base*86400, base), IF(REGEXMATCH(base,"":""), VALUE(LEFT(base, FIND("":"",base)-1))*60 + VALUE(MID(base, FIND("":"",base)+1, 99)), VALUE(SUBSTITUTE(base,"","",""."")))), tSec, IF(ISNUMBER(t), IF(t<1, t*86400, t), "&" IF(REGEXMATCH(t,"":""), VALUE(LEFT(t, FIND("":"",t)-1))*60 + VALUE(MID(t, FIND("":"",t)+1, 99)), VALUE(SUBSTITUTE(t,"","",""."")))), INT(1000*(baseSec/tSec)^3) )"),793.0) -> 793
A8: M | B8: 100 Back | C8: 55.99 | D8: =IFERROR(__xludf.DUMMYFUNCTION("LET( gen,$A8, ev,$B8, t,$C8, hdrs, ARRAYFORMULA(UPPER(TRIM(CLEAN(SUBSTITUTE('AQUA POINTS'!$1:$1,CHAR(160),"" ""))))), col, MATCH(UPPER(ev), hdrs, 0), base, INDEX('AQUA POINTS'!$1:$3, IF(gen=""M"",2,3), col), baseSec, IF(ISNUMBER(base), IF(base<"&"1, base*86400, base), IF(REGEXMATCH(base,"":""), VALUE(LEFT(base, FIND("":"",base)-1))*60 + VALUE(MID(base, FIND("":"",base)+1, 99)), VALUE(SUBSTITUTE(base,"","",""."")))), tSec, IF(ISNUMBER(t), IF(t<1, t*86400, t), "&" IF(REGEXMATCH(t,"":""), VALUE(LEFT(t, FIND("":"",t)-1))*60 + VALUE(MID(t, FIND("":"",t)+1, 99)), VALUE(SUBSTITUTE(t,"","",""."")))), INT(1000*(baseSec/tSec)^3) )"),782.0) -> 782
A9: M | B9: 200 Back | C9: 121.74 | D9: =IFERROR(__xludf.DUMMYFUNCTION("LET( gen,$A9, ev,$B9, t,$C9, hdrs, ARRAYFORMULA(UPPER(TRIM(CLEAN(SUBSTITUTE('AQUA POINTS'!$1:$1,CHAR(160),"" ""))))), col, MATCH(UPPER(ev), hdrs, 0), base, INDEX('AQUA POINTS'!$1:$3, IF(gen=""M"",2,3), col), baseSec, IF(ISNUMBER(base), IF(base<"&"1, base*86400, base), IF(REGEXMATCH(base,"":""), VALUE(LEFT(base, FIND("":"",base)-1))*60 + VALUE(MID(base, FIND("":"",base)+1, 99)), VALUE(SUBSTITUTE(base,"","",""."")))), tSec, IF(ISNUMBER(t), IF(t<1, t*86400, t), "&" IF(REGEXMATCH(t,"":""), VALUE(LEFT(t, FIND("":"",t)-1))*60 + VALUE(MID(t, FIND("":"",t)+1, 99)), VALUE(SUBSTITUTE(t,"","",""."")))), INT(1000*(baseSec/tSec)^3) )"),777.0) -> 777
A10: M | B10: 100 Breast | C10: 62.22 | D10: =IFERROR(__xludf.DUMMYFUNCTION("LET( gen,$A10, ev,$B10, t,$C10, hdrs, ARRAYFORMULA(UPPER(TRIM(CLEAN(SUBSTITUTE('AQUA POINTS'!$1:$1,CHAR(160),"" ""))))), col, MATCH(UPPER(ev), hdrs, 0), base, INDEX('AQUA POINTS'!$1:$3, IF(gen=""M"",2,3), col), baseSec, IF(ISNUMBER(base), IF(ba"&"se<1, base*86400, base), IF(REGEXMATCH(base,"":""), VALUE(LEFT(base, FIND("":"",base)-1))*60 + VALUE(MID(base, FIND("":"",base)+1, 99)), VALUE(SUBSTITUTE(base,"","",""."")))), tSec, IF(ISNUMBER(t), IF(t<1, t*86400, t), "&" IF(REGEXMATCH(t,"":""), VALUE(LEFT(t, FIND("":"",t)-1))*60 + VALUE(MID(t, FIND("":"",t)+1, 99)), VALUE(SUBSTITUTE(t,"","",""."")))), INT(1000*(baseSec/tSec)^3) )"),763.0) -> 763
A11: M | B11: 200 Breast | C11: 134.3 | D11: =IFERROR(__xludf.DUMMYFUNCTION("LET( gen,$A11, ev,$B11, t,$C11, hdrs, ARRAYFORMULA(UPPER(TRIM(CLEAN(SUBSTITUTE('AQUA POINTS'!$1:$1,CHAR(160),"" ""))))), col, MATCH(UPPER(ev), hdrs, 0), base, INDEX('AQUA POINTS'!$1:$3, IF(gen=""M"",2,3), col), baseSec, IF(ISNUMBER(base), IF(ba"&"se<1, base*86400, base), IF(REGEXMATCH(base,"":""), VALUE(LEFT(base, FIND("":"",base)-1))*60 + VALUE(MID(base, FIND("":"",base)+1, 99)), VALUE(SUBSTITUTE(base,"","",""."")))), tSec, IF(ISNUMBER(t), IF(t<1, t*86400, t), "&" IF(REGEXMATCH(t,"":""), VALUE(LEFT(t, FIND("":"",t)-1))*60 + VALUE(MID(t, FIND("":"",t)+1, 99)), VALUE(SUBSTITUTE(t,"","",""."")))), INT(1000*(baseSec/tSec)^3) )"),815.0) -> 815
A12: M | B12: 100 Fly | C12: 52.91 | D12: =IFERROR(__xludf.DUMMYFUNCTION("LET( gen,$A12, ev,$B12, t,$C12, hdrs, ARRAYFORMULA(UPPER(TRIM(CLEAN(SUBSTITUTE('AQUA POINTS'!$1:$1,CHAR(160),"" ""))))), col, MATCH(UPPER(ev), hdrs, 0), base, INDEX('AQUA POINTS'!$1:$3, IF(gen=""M"",2,3), col), baseSec, IF(ISNUMBER(base), IF(ba"&"se<1, base*86400, base), IF(REGEXMATCH(base,"":""), VALUE(LEFT(base, FIND("":"",base)-1))*60 + VALUE(MID(base, FIND("":"",base)+1, 99)), VALUE(SUBSTITUTE(base,"","",""."")))), tSec, IF(ISNUMBER(t), IF(t<1, t*86400, t), "&" IF(REGEXMATCH(t,"":""), VALUE(LEFT(t, FIND("":"",t)-1))*60 + VALUE(MID(t, FIND("":"",t)+1, 99)), VALUE(SUBSTITUTE(t,"","",""."")))), INT(1000*(baseSec/tSec)^3) )"),816.0) -> 816
A13: M | B13: 200 Fly | C13: 120.6 | D13: =IFERROR(__xludf.DUMMYFUNCTION("LET( gen,$A13, ev,$B13, t,$C13, hdrs, ARRAYFORMULA(UPPER(TRIM(CLEAN(SUBSTITUTE('AQUA POINTS'!$1:$1,CHAR(160),"" ""))))), col, MATCH(UPPER(ev), hdrs, 0), base, INDEX('AQUA POINTS'!$1:$3, IF(gen=""M"",2,3), col), baseSec, IF(ISNUMBER(base), IF(ba"&"se<1, base*86400, base), IF(REGEXMATCH(base,"":""), VALUE(LEFT(base, FIND("":"",base)-1))*60 + VALUE(MID(base, FIND("":"",base)+1, 99)), VALUE(SUBSTITUTE(base,"","",""."")))), tSec, IF(ISNUMBER(t), IF(t<1, t*86400, t), "&" IF(REGEXMATCH(t,"":""), VALUE(LEFT(t, FIND("":"",t)-1))*60 + VALUE(MID(t, FIND("":"",t)+1, 99)), VALUE(SUBSTITUTE(t,"","",""."")))), INT(1000*(baseSec/tSec)^3) )"),765.0) -> 765
A14: M | B14: 200 IM | C14: 122.42 | D14: =IFERROR(__xludf.DUMMYFUNCTION("LET( gen,$A14, ev,$B14, t,$C14, hdrs, ARRAYFORMULA(UPPER(TRIM(CLEAN(SUBSTITUTE('AQUA POINTS'!$1:$1,CHAR(160),"" ""))))), col, MATCH(UPPER(ev), hdrs, 0), base, INDEX('AQUA POINTS'!$1:$3, IF(gen=""M"",2,3), col), baseSec, IF(ISNUMBER(base), IF(ba"&"se<1, base*86400, base), IF(REGEXMATCH(base,"":""), VALUE(LEFT(base, FIND("":"",base)-1))*60 + VALUE(MID(base, FIND("":"",base)+1, 99)), VALUE(SUBSTITUTE(base,"","",""."")))), tSec, IF(ISNUMBER(t), IF(t<1, t*86400, t), "&" IF(REGEXMATCH(t,"":""), VALUE(LEFT(t, FIND("":"",t)-1))*60 + VALUE(MID(t, FIND("":"",t)+1, 99)), VALUE(SUBSTITUTE(t,"","",""."")))), INT(1000*(baseSec/tSec)^3) )"),807.0) -> 807
A15: M | B15: 400 IM | C15: 263.24 | D15: =IFERROR(__xludf.DUMMYFUNCTION("LET( gen,$A15, ev,$B15, t,$C15, hdrs, ARRAYFORMULA(UPPER(TRIM(CLEAN(SUBSTITUTE('AQUA POINTS'!$1:$1,CHAR(160),"" ""))))), col, MATCH(UPPER(ev), hdrs, 0), base, INDEX('AQUA POINTS'!$1:$3, IF(gen=""M"",2,3), col), baseSec, IF(ISNUMBER(base), IF(ba"&"se<1, base*86400, base), IF(REGEXMATCH(base,"":""), VALUE(LEFT(base, FIND("":"",base)-1))*60 + VALUE(MID(base, FIND("":"",base)+1, 99)), VALUE(SUBSTITUTE(base,"","",""."")))), tSec, IF(ISNUMBER(t), IF(t<1, t*86400, t), "&" IF(REGEXMATCH(t,"":""), VALUE(LEFT(t, FIND("":"",t)-1))*60 + VALUE(MID(t, FIND("":"",t)+1, 99)), VALUE(SUBSTITUTE(t,"","",""."")))), INT(1000*(baseSec/tSec)^3) )"),781.0) -> 781
